Workbook

Sheet AGEN BAOMEKOT
B3: DIGIPOS R2 CELL 082144228240 | I3: EDC SEFTIANUS RUBEN FA494427 | O3: BRILINK THYAND 357201028758536 | Z3: 3 SAKTI THYAND 089512732555 | AF3: SIMPEL IM3 THYAND 085745584943 AgenkiosR2$ | AN3: PEGADAIAN THYAND + 2437 082147266855 | AU3: BRILINK BARU THYAND 011901070079503
B4: TOP UP | C4: HARGA JUAL | D4: HARGA MODAL | E4: SALDO | F4: BIAYA | I4: TARIK / TOP UP | J4: TRANSFER | K4: SALDO | L4: HARGA JUAL | M4: BIAYA | O4: TOP UP | P4: TARIK TUNAI | Q4: BRIMO | R4: TRANSFER BRI | S4: LAINNYA | T4: ADMIN BANK | U4: FEE | V4: SALDO | W4: BIAYA | Z4: TARIK / TOP UP | AA4: TRANSFER | AB4: SALDO | AC4: HARGA JUAL | AD4: BIAYA | AF4: TARIK / TOP UP | AG4: TRANSFER | AH4: SALDO | AI4: HARGA JUAL | AJ4: BIAYA | AN4: TOP UP | AO4: TRANSFER KELUAR | AP4: KOMISI | AQ4: SALDO | AR4: HARGA BAYAR | AS4: BIAYA | AU4: TOP UP | AV4: TARIK TUNAI | AW4: BRIMO | AX4: TRANSFER BRI | AY4: LAINNYA | AZ4: ADMIN BANK | BA4: FEE | BB4: SALDO | BC4: BIAYA | BE4: SALDO AWAL
E5: ='TABEL INPUT'!C4 -> 337945 | K5: ='TABEL INPUT'!C7 -> 941317 | M5: =L5-J5 -> 0 | V5: ='TABEL INPUT'!C5 -> 14081391 | AB5: ='TABEL INPUT'!C9 -> 638 | AD5: =AC5-AA5 -> 0 | AH5: ='TABEL INPUT'!C10 -> 320270 | AJ5: =AI5-AG5 -> 0 | AQ5: ='TABEL INPUT'!C8 -> 199895 | AS5: =AR5-AO5 -> 0 | BB5: 0 | BE5: SALDO | BF5: =E5+K5+V5+AB5+AH5+AQ5+BB5 -> 15881456 | BG5: =BF5+BF6+BF7 -> 40881456
E6: =E5+B6-D6 -> 337945 | F6: =C6-D6 -> 0 | K6: =K5+I6-J6 -> 941317 | M6: =L6-J6 -> 0 | V6: =V5+O6+P6-Q6-R6-S6-T6+U6 -> 14081391 | W6: ='TABEL INPUT'!C32 -> 0 | AB6: =AB5+Z6-AA6 -> 638 | AD6: =AC6-AA6 -> 0 | AH6: =AH5+AF6-AG6 -> 320270 | AJ6: =AI6-AG6 -> 0 | AQ6: =AQ5+AN6-AO6+AP6 -> 199895 | AS6: =AR6-AO6 -> 0 | BB6: =BB5+AU6+AV6-AW6-AX6-AY6-AZ6+BA6 -> 0 | BC6: 0 | BE6: TUNAI | BF6: 25000000
E7: =E6+B7-D7 -> 337945 | F7: =C7-D7 -> 0 | K7: =K6+I7-J7 -> 941317 | M7: =L7-J7 -> 0 | V7: =V6+O7+P7-Q7-R7-S7-T7+U7 -> 14081391 | W7: ='TABEL INPUT'!C33 -> 0 | AB7: =AB6+Z7-AA7 -> 638 | AD7: =AC7-AA7 -> 0 | AH7: =AH6+AF7-AG7 -> 320270 | AJ7: =AI7-AG7 -> 0 | AQ7: =AQ6+AN7-AO7+AP7 -> 199895 | AS7: =AR7-AO7 -> 0 | BB7: =BB6+AU7+AV7-AW7-AX7-AY7-AZ7+BA7 -> 0 | BC7: 0 | BE7: UANG KECIL
E8: =E7+B8-D8 -> 337945 | F8: =C8-D8 -> 0 | K8: =K7+I8-J8 -> 941317 | M8: =L8-J8 -> 0 | V8: =V7+O8+P8-Q8-R8-S8-T8+U8 -> 14081391 | W8: ='TABEL INPUT'!C34 -> 0 | AB8: =AB7+Z8-AA8 -> 638 | AD8: =AC8-AA8 -> 0 | AH8: =AH7+AF8-AG8 -> 320270 | AJ8: =AI8-AG8 -> 0 | AQ8: =AQ7+AN8-AO8+AP8 -> 199895 | AS8: =AR8-AO8 -> 0 | BB8: =BB7+AU8+AV8-AW8-AX8-AY8-AZ8+BA8 -> 0 | BC8: 0 | BE8: HUTANG
E9: =E8+B9-D9 -> 337945 | F9: =C9-D9 -> 0 | K9: =K8+I9-J9 -> 941317 | M9: =L9-J9 -> 0 | V9: =V8+O9+P9-Q9-R9-S9-T9+U9 -> 14081391 | W9: ='TABEL INPUT'!C35 -> 0 | AB9: =AB8+Z9-AA9 -> 638 | AD9: =AC9-AA9 -> 0 | AH9: =AH8+AF9-AG9 -> 320270 | AJ9: =AI9-AG9 -> 0 | AM9: 0 | AQ9: =AQ8+AN9-AO9+AP9 -> 199895 | AS9: =AR9-AO9 -> 0 | BB9: =BB8+AU9+AV9-AW9-AX9-AY9-AZ9+BA9 -> 0 | BC9: 0 | BE9: PIUTANG
E10: =E9+B10-D10 -> 337945 | F10: =C10-D10 -> 0 | K10: =K9+I10-J10 -> 941317 | M10: =L10-J10 -> 0 | V10: =V9+O10+P10-Q10-R10-S10-T10+U10 -> 14081391 | W10: ='TABEL INPUT'!C36 -> 0 | AB10: =AB9+Z10-AA10 -> 638 | AD10: =AC10-AA10 -> 0 | AH10: =AH9+AF10-AG10 -> 320270 | AJ10: =AI10-AG10 -> 0 | AQ10: =AQ9+AN10-AO10+AP10 -> 199895 | AS10: =AR10-AO10 -> 0 | BB10: =BB9+AU10+AV10-AW10-AX10-AY10-AZ10+BA10 -> 0 | BC10: 0
E11: =E10+B11-D11 -> 337945 | F11: =C11-D11 -> 0 | K11: =K10+I11-J11 -> 941317 | M11: =L11-J11 -> 0 | V11: =V10+O11+P11-Q11-R11-S11-T11+U11 -> 14081391 | W11: ='TABEL INPUT'!C37 -> 0 | AB11: =AB10+Z11-AA11 -> 638 | AD11: =AC11-AA11 -> 0 | AH11: =AH10+AF11-AG11 -> 320270 | AJ11: =AI11-AG11 -> 0 | AQ11: =AQ10+AN11-AO11+AP11 -> 199895 | AS11: =AR11-AO11 -> 0 | BB11: =BB10+AU11+AV11-AW11-AX11-AY11-AZ11+BA11 -> 0 | BC11: 0
E12: =E11+B12-D12 -> 337945 | F12: =C12-D12 -> 0 | K12: =K11+I12-J12 -> 941317 | M12: =L12-J12 -> 0 | V12: =V11+O12+P12-Q12-R12-S12-T12+U12 -> 14081391 | W12: ='TABEL INPUT'!C38 -> 0 | AB12: =AB11+Z12-AA12 -> 638 | AD12: =AC12-AA12 -> 0 | AH12: =AH11+AF12-AG12 -> 320270 | AJ12: =AI12-AG12 -> 0 | AQ12: =AQ11+AN12-AO12+AP12 -> 199895 | AS12: =AR12-AO12 -> 0 | BB12: =BB11+AU12+AV12-AW12-AX12-AY12-AZ12+BA12 -> 0 | BC12: 0
E13: =E12+B13-D13 -> 337945 | F13: =C13-D13 -> 0 | K13: =K12+I13-J13 -> 941317 | M13: =L13-J13 -> 0 | V13: =V12+O13+P13-Q13-R13-S13-T13+U13 -> 14081391 | AB13: =AB12+Z13-AA13 -> 638 | AD13: =AC13-AA13 -> 0 | AH13: =AH12+AF13-AG13 -> 320270 | AJ13: =AI13-AG13 -> 0 | AQ13: =AQ12+AN13-AO13+AP13 -> 199895 | AS13: =AR13-AO13 -> 0 | BB13: =BB12+AU13+AV13-AW13-AX13-AY13-AZ13+BA13 -> 0 | BC13: 0 | BE13: SALDO AKHIR
E14: =E13+B14-D14 -> 337945 | F14: =C14-D14 -> 0 | K14: =K13+I14-J14 -> 941317 | M14: =L14-J14 -> 0 | V14: =V13+O14+P14-Q14-R14-S14-T14+U14 -> 14081391 | AB14: =AB13+Z14-AA14 -> 638 | AD14: =AC14-AA14 -> 0 | AH14: =AH13+AF14-AG14 -> 320270 | AJ14: =AI14-AG14 -> 0 | AQ14: =AQ13+AN14-AO14+AP14 -> 199895 | AS14: =AR14-AO14 -> 0 | BB14: =BB13+AU14+AV14-AW14-AX14-AY14-AZ14+BA14 -> 0 | BC14: 0 | BE14: SALDO | BF14: =E190+K190+V190+AB190+AH190+AQ190+BB190 -> 15881456 | BG14: =BF14+BF15+BF16 -> 15881456
E15: =E14+B15-D15 -> 337945 | F15: =C15-D15 -> 0 | K15: =K14+I15-J15 -> 941317 | M15: =L15-J15 -> 0 | V15: =V14+O15+P15-Q15-R15-S15-T15+U15 -> 14081391 | AB15: =AB14+Z15-AA15 -> 638 | AD15: =AC15-AA15 -> 0 | AH15: =AH14+AF15-AG15 -> 320270 | AJ15: =AI15-AG15 -> 0 | AQ15: =AQ14+AN15-AO15+AP15 -> 199895 | AS15: =AR15-AO15 -> 0 | BB15: =BB14+AU15+AV15-AW15-AX15-AY15-AZ15+BA15 -> 0 | BC15: 0 | BE15: TUNAI | BF15: 0
E16: =E15+B16-D16 -> 337945 | F16: =C16-D16 -> 0 | K16: =K15+I16-J16 -> 941317 | M16: =L16-J16 -> 0 | V16: =V15+O16+P16-Q16-R16-S16-T16+U16 -> 14081391 | AB16: =AB15+Z16-AA16 -> 638 | AD16: =AC16-AA16 -> 0 | AH16: =AH15+AF16-AG16 -> 320270 | AJ16: =AI16-AG16 -> 0 | AQ16: =AQ15+AN16-AO16+AP16 -> 199895 | AS16: =AR16-AO16 -> 0 | BB16: =BB15+AU16+AV16-AW16-AX16-AY16-AZ16+BA16 -> 0 | BC16: 0 | BE16: UANG KECIL
E17: =E16+B17-D17 -> 337945 | F17: =C17-D17 -> 0 | K17: =K16+I17-J17 -> 941317 | M17: =L17-J17 -> 0 | V17: =V16+O17+P17-Q17-R17-S17-T17+U17 -> 14081391 | AB17: =AB16+Z17-AA17 -> 638 | AD17: =AC17-AA17 -> 0 | AH17: =AH16+AF17-AG17 -> 320270 | AJ17: =AI17-AG17 -> 0 | AQ17: =AQ16+AN17-AO17+AP17 -> 199895 | AS17: =AR17-AO17 -> 0 | BB17: =BB16+AU17+AV17-AW17-AX17-AY17-AZ17+BA17 -> 0 | BC17: 0 | BE17: HUTANG
E18: =E17+B18-D18 -> 337945 | F18: =C18-D18 -> 0 | K18: =K17+I18-J18 -> 941317 | M18: =L18-J18 -> 0 | V18: =V17+O18+P18-Q18-R18-S18-T18+U18 -> 14081391 | AB18: =AB17+Z18-AA18 -> 638 | AD18: =AC18-AA18 -> 0 | AH18: =AH17+AF18-AG18 -> 320270 | AJ18: =AI18-AG18 -> 0 | AQ18: =AQ17+AN18-AO18+AP18 -> 199895 | AS18: =AR18-AO18 -> 0 | BB18: =BB17+AU18+AV18-AW18-AX18-AY18-AZ18+BA18 -> 0 | BC18: 0 | BE18: PIUTANG
E19: =E18+B19-D19 -> 337945 | F19: =C19-D19 -> 0 | K19: =K18+I19-J19 -> 941317 | M19: =L19-J19 -> 0 | V19: =V18+O19+P19-Q19-R19-S19-T19+U19 -> 14081391 | AB19: =AB18+Z19-AA19 -> 638 | AD19: =AC19-AA19 -> 0 | AH19: =AH18+AF19-AG19 -> 320270 | AJ19: =AI19-AG19 -> 0 | AQ19: =AQ18+AN19-AO19+AP19 -> 199895 | AS19: =AR19-AO19 -> 0 | BB19: =BB18+AU19+AV19-AW19-AX19-AY19-AZ19+BA19 -> 0 | BC19: 0
E20: =E19+B20-D20 -> 337945 | F20: =C20-D20 -> 0 | K20: =K19+I20-J20 -> 941317 | M20: =L20-J20 -> 0 | V20: =V19+O20+P20-Q20-R20-S20-T20+U20 -> 14081391 | AB20: =AB19+Z20-AA20 -> 638 | AD20: =AC20-AA20 -> 0 | AH20: =AH19+AF20-AG20 -> 320270 | AJ20: =AI20-AG20 -> 0 | AQ20: =AQ19+AN20-AO20+AP20 -> 199895 | AS20: =AR20-AO20 -> 0 | BB20: =BB19+AU20+AV20-AW20-AX20-AY20-AZ20+BA20 -> 0 | BC20: 0
E21: =E20+B21-D21 -> 337945 | F21: =C21-D21 -> 0 | K21: =K20+I21-J21 -> 941317 | M21: =L21-J21 -> 0 | V21: =V20+O21+P21-Q21-R21-S21-T21+U21 -> 14081391 | AB21: =AB20+Z21-AA21 -> 638 | AD21: =AC21-AA21 -> 0 | AH21: =AH20+AF21-AG21 -> 320270 | AJ21: =AI21-AG21 -> 0 | AQ21: =AQ20+AN21-AO21+AP21 -> 199895 | AS21: =AR21-AO21 -> 0 | BB21: =BB20+AU21+AV21-AW21-AX21-AY21-AZ21+BA21 -> 0 | BC21: 0
E22: =E21+B22-D22 -> 337945 | F22: =C22-D22 -> 0 | K22: =K21+I22-J22 -> 941317 | M22: =L22-J22 -> 0 | V22: =V21+O22+P22-Q22-R22-S22-T22+U22 -> 14081391 | AB22: =AB21+Z22-AA22 -> 638 | AD22: =AC22-AA22 -> 0 | AH22: =AH21+AF22-AG22 -> 320270 | AJ22: =AI22-AG22 -> 0 | AQ22: =AQ21+AN22-AO22+AP22 -> 199895 | AS22: =AR22-AO22 -> 0 | BB22: =BB21+AU22+AV22-AW22-AX22-AY22-AZ22+BA22 -> 0 | BC22: 0 | BE22: PEMASUKAN | BF22: =F191+M191+U191+W191+AD191+AJ191+AP191+AS191+BC191 -> 0
E23: =E22+B23-D23 -> 337945 | F23: =C23-D23 -> 0 | K23: =K22+I23-J23 -> 941317 | M23: =L23-J23 -> 0 | V23: =V22+O23+P23-Q23-R23-S23-T23+U23 -> 14081391 | AB23: =AB22+Z23-AA23 -> 638 | AD23: =AC23-AA23 -> 0 | AH23: =AH22+AF23-AG23 -> 320270 | AJ23: =AI23-AG23 -> 0 | AQ23: =AQ22+AN23-AO23+AP23 -> 199895 | AS23: =AR23-AO23 -> 0 | BB23: =BB22+AU23+AV23-AW23-AX23-AY23-AZ23+BA23 -> 0 | BC23: 0
E24: =E23+B24-D24 -> 337945 | F24: =C24-D24 -> 0 | K24: =K23+I24-J24 -> 941317 | M24: =L24-J24 -> 0 | V24: =V23+O24+P24-Q24-R24-S24-T24+U24 -> 14081391 | AB24: =AB23+Z24-AA24 -> 638 | AD24: =AC24-AA24 -> 0 | AH24: =AH23+AF24-AG24 -> 320270 | AJ24: =AI24-AG24 -> 0 | AQ24: =AQ23+AN24-AO24+AP24 -> 199895 | AS24: =AR24-AO24 -> 0 | BB24: =BB23+AU24+AV24-AW24-AX24-AY24-AZ24+BA24 -> 0 | BC24: 0
E25: =E24+B25-D25 -> 337945 | F25: =C25-D25 -> 0 | K25: =K24+I25-J25 -> 941317 | M25: =L25-J25 -> 0 | V25: =V24+O25+P25-Q25-R25-S25-T25+U25 -> 14081391 | AB25: =AB24+Z25-AA25 -> 638 | AD25: =AC25-AA25 -> 0 | AH25: =AH24+AF25-AG25 -> 320270 | AJ25: =AI25-AG25 -> 0 | AQ25: =AQ24+AN25-AO25+AP25 -> 199895 | AS25: =AR25-AO25 -> 0 | BB25: =BB24+AU25+AV25-AW25-AX25-AY25-AZ25+BA25 -> 0 | BC25: 0 | BE25: PENGELUARAN
E26: =E25+B26-D26 -> 337945 | F26: =C26-D26 -> 0 | K26: =K25+I26-J26 -> 941317 | M26: =L26-J26 -> 0 | V26: =V25+O26+P26-Q26-R26-S26-T26+U26 -> 14081391 | AB26: =AB25+Z26-AA26 -> 638 | AD26: =AC26-AA26 -> 0 | AH26: =AH25+AF26-AG26 -> 320270 | AJ26: =AI26-AG26 -> 0 | AQ26: =AQ25+AN26-AO26+AP26 -> 199895 | AS26: =AR26-AO26 -> 0 | BB26: =BB25+AU26+AV26-AW26-AX26-AY26-AZ26+BA26 -> 0 | BC26: 0 | BE26: BIAYA TOP UP | BF26: ='TABEL INPUT'!C43 -> 0 | BI26: =SUM(BF26:BH26) -> 0
E27: =E26+B27-D27 -> 337945 | F27: =C27-D27 -> 0 | K27: =K26+I27-J27 -> 941317 | M27: =L27-J27 -> 0 | V27: =V26+O27+P27-Q27-R27-S27-T27+U27 -> 14081391 | AB27: =AB26+Z27-AA27 -> 638 | AD27: =AC27-AA27 -> 0 | AH27: =AH26+AF27-AG27 -> 320270 | AJ27: =AI27-AG27 -> 0 | AQ27: =AQ26+AN27-AO27+AP27 -> 199895 | AS27: =AR27-AO27 -> 0 | BB27: =BB26+AU27+AV27-AW27-AX27-AY27-AZ27+BA27 -> 0 | BC27: 0 | BE27: ADMIN BULANAN | BF27: ='TABEL INPUT'!C44 -> 0 | BI27: =SUM(BF27:BH27) -> 0
E28: =E27+B28-D28 -> 337945 | F28: =C28-D28 -> 0 | K28: =K27+I28-J28 -> 941317 | M28: =L28-J28 -> 0 | V28: =V27+O28+P28-Q28-R28-S28-T28+U28 -> 14081391 | AB28: =AB27+Z28-AA28 -> 638 | AD28: =AC28-AA28 -> 0 | AH28: =AH27+AF28-AG28 -> 320270 | AJ28: =AI28-AG28 -> 0 | AQ28: =AQ27+AN28-AO28+AP28 -> 199895 | AS28: =AR28-AO28 -> 0 | BB28: =BB27+AU28+AV28-AW28-AX28-AY28-AZ28+BA28 -> 0 | BC28: 0 | BE28: DATA | BF28: ='TABEL INPUT'!C45 -> 0 | BI28: =SUM(BF28:BH28) -> 0
E29: =E28+B29-D29 -> 337945 | F29: =C29-D29 -> 0 | K29: =K28+I29-J29 -> 941317 | M29: =L29-J29 -> 0 | V29: =V28+O29+P29-Q29-R29-S29-T29+U29 -> 14081391 | AB29: =AB28+Z29-AA29 -> 638 | AD29: =AC29-AA29 -> 0 | AH29: =AH28+AF29-AG29 -> 320270 | AJ29: =AI29-AG29 -> 0 | AQ29: =AQ28+AN29-AO29+AP29 -> 199895 | AS29: =AR29-AO29 -> 0 | BB29: =BB28+AU29+AV29-AW29-AX29-AY29-AZ29+BA29 -> 0 | BC29: 0 | BE29: AIR GALON | BF29: ='TABEL INPUT'!C46 -> 0 | BI29: =SUM(BF29:BH29) -> 0
E30: =E29+B30-D30 -> 337945 | F30: =C30-D30 -> 0 | K30: =K29+I30-J30 -> 941317 | M30: =L30-J30 -> 0 | V30: =V29+O30+P30-Q30-R30-S30-T30+U30 -> 14081391 | AB30: =AB29+Z30-AA30 -> 638 | AD30: =AC30-AA30 -> 0 | AH30: =AH29+AF30-AG30 -> 320270 | AJ30: =AI30-AG30 -> 0 | AQ30: =AQ29+AN30-AO30+AP30 -> 199895 | AS30: =AR30-AO30 -> 0 | BB30: =BB29+AU30+AV30-AW30-AX30-AY30-AZ30+BA30 -> 0 | BC30: 0 | BE30: LISTRIK | BF30: ='TABEL INPUT'!C47 -> 0 | BI30: =SUM(BF30:BH30) -> 0
E31: =E30+B31-D31 -> 337945 | F31: =C31-D31 -> 0 | K31: =K30+I31-J31 -> 941317 | M31: =L31-J31 -> 0 | V31: =V30+O31+P31-Q31-R31-S31-T31+U31 -> 14081391 | AB31: =AB30+Z31-AA31 -> 638 | AD31: =AC31-AA31 -> 0 | AH31: =AH30+AF31-AG31 -> 320270 | AJ31: =AI31-AG31 -> 0 | AQ31: =AQ30+AN31-AO31+AP31 -> 199895 | AS31: =AR31-AO31 -> 0 | BB31: =BB30+AU31+AV31-AW31-AX31-AY31-AZ31+BA31 -> 0 | BC31: 0 | BE31: GAJI KARYAWAN | BF31: ='TABEL INPUT'!C48 -> 0 | BI31: =SUM(BF31:BH31) -> 0
E32: =E31+B32-D32 -> 337945 | F32: =C32-D32 -> 0 | K32: =K31+I32-J32 -> 941317 | M32: =L32-J32 -> 0 | V32: =V31+O32+P32-Q32-R32-S32-T32+U32 -> 14081391 | AB32: =AB31+Z32-AA32 -> 638 | AD32: =AC32-AA32 -> 0 | AH32: =AH31+AF32-AG32 -> 320270 | AJ32: =AI32-AG32 -> 0 | AQ32: =AQ31+AN32-AO32+AP32 -> 199895 | AS32: =AR32-AO32 -> 0 | BB32: =BB31+AU32+AV32-AW32-AX32-AY32-AZ32+BA32 -> 0 | BC32: 0 | BE32: ELINK | BF32: ='TABEL INPUT'!C49 -> 0 | BI32: =SUM(BF32:BH32) -> 0
E33: =E32+B33-D33 -> 337945 | F33: =C33-D33 -> 0 | K33: =K32+I33-J33 -> 941317 | M33: =L33-J33 -> 0 | V33: =V32+O33+P33-Q33-R33-S33-T33+U33 -> 14081391 | AB33: =AB32+Z33-AA33 -> 638 | AD33: =AC33-AA33 -> 0 | AH33: =AH32+AF33-AG33 -> 320270 | AJ33: =AI33-AG33 -> 0 | AQ33: =AQ32+AN33-AO33+AP33 -> 199895 | AS33: =AR33-AO33 -> 0 | BB33: =BB32+AU33+AV33-AW33-AX33-AY33-AZ33+BA33 -> 0 | BC33: 0 | BE33: SEWA TEMPAT | BF33: ='TABEL INPUT'!C50 -> 0 | BI33: =SUM(BF33:BH33) -> 0
E34: =E33+B34-D34 -> 337945 | F34: =C34-D34 -> 0 | K34: =K33+I34-J34 -> 941317 | M34: =L34-J34 -> 0 | V34: =V33+O34+P34-Q34-R34-S34-T34+U34 -> 14081391 | AB34: =AB33+Z34-AA34 -> 638 | AD34: =AC34-AA34 -> 0 | AH34: =AH33+AF34-AG34 -> 320270 | AJ34: =AI34-AG34 -> 0 | AQ34: =AQ33+AN34-AO34+AP34 -> 199895 | AS34: =AR34-AO34 -> 0 | BB34: =BB33+AU34+AV34-AW34-AX34-AY34-AZ34+BA34 -> 0 | BC34: 0 | BE34: LAINNYA | BF34: ='TABEL INPUT'!C52 -> 0 | BI34: =SUM(BF34:BH34) -> 0
E35: =E34+B35-D35 -> 337945 | F35: =C35-D35 -> 0 | K35: =K34+I35-J35 -> 941317 | M35: =L35-J35 -> 0 | V35: =V34+O35+P35-Q35-R35-S35-T35+U35 -> 14081391 | AB35: =AB34+Z35-AA35 -> 638 | AD35: =AC35-AA35 -> 0 | AH35: =AH34+AF35-AG35 -> 320270 | AJ35: =AI35-AG35 -> 0 | AQ35: =AQ34+AN35-AO35+AP35 -> 199895 | AS35: =AR35-AO35 -> 0 | BB35: =BB34+AU35+AV35-AW35-AX35-AY35-AZ35+BA35 -> 0 | BC35: 0
E36: =E35+B36-D36 -> 337945 | F36: =C36-D36 -> 0 | K36: =K35+I36-J36 -> 941317 | M36: =L36-J36 -> 0 | V36: =V35+O36+P36-Q36-R36-S36-T36+U36 -> 14081391 | AB36: =AB35+Z36-AA36 -> 638 | AD36: =AC36-AA36 -> 0 | AH36: =AH35+AF36-AG36 -> 320270 | AJ36: =AI36-AG36 -> 0 | AQ36: =AQ35+AN36-AO36+AP36 -> 199895 | AS36: =AR36-AO36 -> 0 | BB36: =BB35+AU36+AV36-AW36-AX36-AY36-AZ36+BA36 -> 0 | BC36: 0 | BE36: TOTAL | BF36: =BI26+BI27+BI28+BI29+BI30+BI31+BI32+BI33+BI34 -> 0
E37: =E36+B37-D37 -> 337945 | F37: =C37-D37 -> 0 | K37: =K36+I37-J37 -> 941317 | M37: =L37-J37 -> 0 | V37: =V36+O37+P37-Q37-R37-S37-T37+U37 -> 14081391 | AB37: =AB36+Z37-AA37 -> 638 | AD37: =AC37-AA37 -> 0 | AH37: =AH36+AF37-AG37 -> 320270 | AJ37: =AI37-AG37 -> 0 | AQ37: =AQ36+AN37-AO37+AP37 -> 199895 | AS37: =AR37-AO37 -> 0 | BB37: =BB36+AU37+AV37-AW37-AX37-AY37-AZ37+BA37 -> 0 | BC37: 0
E38: =E37+B38-D38 -> 337945 | F38: =C38-D38 -> 0 | K38: =K37+I38-J38 -> 941317 | M38: =L38-J38 -> 0 | V38: =V37+O38+P38-Q38-R38-S38-T38+U38 -> 14081391 | AB38: =AB37+Z38-AA38 -> 638 | AD38: =AC38-AA38 -> 0 | AH38: =AH37+AF38-AG38 -> 320270 | AJ38: =AI38-AG38 -> 0 | AQ38: =AQ37+AN38-AO38+AP38 -> 199895 | AS38: =AR38-AO38 -> 0 | BB38: =BB37+AU38+AV38-AW38-AX38-AY38-AZ38+BA38 -> 0 | BC38: 0
E39: =E38+B39-D39 -> 337945 | F39: =C39-D39 -> 0 | K39: =K38+I39-J39 -> 941317 | M39: =L39-J39 -> 0 | V39: =V38+O39+P39-Q39-R39-S39-T39+U39 -> 14081391 | AB39: =AB38+Z39-AA39 -> 638 | AD39: =AC39-AA39 -> 0 | AH39: =AH38+AF39-AG39 -> 320270 | AJ39: =AI39-AG39 -> 0 | AQ39: =AQ38+AN39-AO39+AP39 -> 199895 | AS39: =AR39-AO39 -> 0 | BB39: =BB38+AU39+AV39-AW39-AX39-AY39-AZ39+BA39 -> 0 | BC39: 0
E40: =E39+B40-D40 -> 337945 | F40: =C40-D40 -> 0 | K40: =K39+I40-J40 -> 941317 | M40: =L40-J40 -> 0 | V40: =V39+O40+P40-Q40-R40-S40-T40+U40 -> 14081391 | AB40: =AB39+Z40-AA40 -> 638 | AD40: =AC40-AA40 -> 0 | AH40: =AH39+AF40-AG40 -> 320270 | AJ40: =AI40-AG40 -> 0 | AQ40: =AQ39+AN40-AO40+AP40 -> 199895 | AS40: =AR40-AO40 -> 0 | BB40: =BB39+AU40+AV40-AW40-AX40-AY40-AZ40+BA40 -> 0 | BC40: 0
E41: =E40+B41-D41 -> 337945 | F41: =C41-D41 -> 0 | K41: =K40+I41-J41 -> 941317 | M41: =L41-J41 -> 0 | V41: =V40+O41+P41-Q41-R41-S41-T41+U41 -> 14081391 | AB41: =AB40+Z41-AA41 -> 638 | AD41: =AC41-AA41 -> 0 | AH41: =AH40+AF41-AG41 -> 320270 | AJ41: =AI41-AG41 -> 0 | AQ41: =AQ40+AN41-AO41+AP41 -> 199895 | AS41: =AR41-AO41 -> 0 | BB41: =BB40+AU41+AV41-AW41-AX41-AY41-AZ41+BA41 -> 0 | BC41: 0
E42: =E41+B42-D42 -> 337945 | F42: =C42-D42 -> 0 | K42: =K41+I42-J42 -> 941317 | M42: =L42-J42 -> 0 | V42: =V41+O42+P42-Q42-R42-S42-T42+U42 -> 14081391 | AB42: =AB41+Z42-AA42 -> 638 | AD42: =AC42-AA42 -> 0 | AH42: =AH41+AF42-AG42 -> 320270 | AJ42: =AI42-AG42 -> 0 | AQ42: =AQ41+AN42-AO42+AP42 -> 199895 | AS42: =AR42-AO42 -> 0 | BB42: =BB41+AU42+AV42-AW42-AX42-AY42-AZ42+BA42 -> 0 | BC42: 0
...

Sheet AGEN SIKU EHA
A3: KIOS | E3: DIGIPOS R2 SIKU EHA 085189220661 | K3: EDC FRANSISKA MARGARETHA FA391817 | R3: BRILINK CHYKA 469301000223502 | AB3: 3 SAKTI CHYKA 08999977283 | AH3: SIMPEL IM3 085702789843 | AP3: PEGADAIAN CHYKA + 2437 | AW3: SIDOMPUL 087788625894
A4: BELANJA | B4: PENJUALAN | E4: TOP UP | F4: HARGA JUAL | G4: HARGA MODAL | H4: SALDO | I4: BIAYA | K4: TARIK / TOP UP | L4: TRANSFER | M4: SALDO | N4: HARGA JUAL | O4: BIAYA | R4: TOP UP | S4: TARIK TUNAI | T4: BRIMO KELUAR | U4: TRANSFER BRI | V4: LAINNYA | W4: ADMIN BANK | X4: FEE | Y4: SALDO | Z4: BIAYA | AB4: TARIK / TOP UP | AC4: TRANSFER | AD4: SALDO | AE4: HARGA JUAL | AF4: BIAYA | AH4: TARIK / TOP UP | AI4: TRANSFER | AJ4: SALDO | AK4: HARGA JUAL | AL4: BIAYA | AP4: TOP UP | AQ4: TRANSFER KELUAR | AR4: KOMISI | AS4: SALDO | AT4: HARGA BAYAR | AU4: BIAYA | AW4: TOP UP | AX4: JUAL PULSA | AY4: HARGA MODAL | AZ4: SALDO | BA4: BIAYA
H5: ='TABEL INPUT'!F4 -> 341717 | M5: ='TABEL INPUT'!F9 -> 975218 | O5: =N5-L5 -> 0 | Y5: ='TABEL INPUT'!F5 -> 5000000 | AD5: ='TABEL INPUT'!F8 -> 528915 | AF5: =AE5-AC5 -> 0 | AJ5: ='TABEL INPUT'!F10 -> 376533 | AL5: =AK5-AI5 -> 0 | AS5: ='TABEL INPUT'!F7 -> 208871 | AU5: =AT5-AQ5 -> 0 | AZ5: 0 | BC5: PENGELUARAN
H6: =H5+E6-G6 -> 341717 | I6: =F6-G6 -> 0 | M6: =SUM(M5+K6-L6) -> 975218 | O6: =N6-L6 -> 0 | Y6: =Y5+R6+S6-T6-U6-V6-W6+X6 -> 5000000 | Z6: ='TABEL INPUT'!F32 -> 0 | AD6: =AD5+AB6-AC6 -> 528915 | AF6: =AE6-AC6 -> 0 | AJ6: =AJ5+AH6-AI6 -> 376533 | AL6: =AK6-AI6 -> 0 | AS6: =AS5+AP6-AQ6+AR6 -> 208871 | AU6: =AT6-AQ6 -> 0 | AZ6: =AZ5+AW6-AY6 -> 0 | BA6: =AX6-AY6 -> 0 | BC6: BIAYA TOP UP | BD6: ='TABEL INPUT'!F43 -> 0 | BG6: =SUM(BD6:BF6) -> 0
H7: =H6+E7-G7 -> 341717 | I7: =F7-G7 -> 0 | M7: =SUM(M6+K7-L7) -> 975218 | O7: =N7-L7 -> 0 | Y7: =Y6+R7+S7-T7-U7-V7-W7+X7 -> 5000000 | Z7: ='TABEL INPUT'!F33 -> 0 | AD7: =AD6+AB7-AC7 -> 528915 | AF7: =AE7-AC7 -> 0 | AJ7: =AJ6+AH7-AI7 -> 376533 | AL7: =AK7-AI7 -> 0 | AS7: =AS6+AP7-AQ7+AR7 -> 208871 | AU7: =AT7-AQ7 -> 0 | AZ7: =AZ6+AW7-AY7 -> 0 | BA7: =AX7-AY7 -> 0 | BC7: ADMIN BULANAN | BD7: ='TABEL INPUT'!F44 -> 0 | BG7: =SUM(BD7:BF7) -> 0
H8: =H7+E8-G8 -> 341717 | I8: =F8-G8 -> 0 | M8: =SUM(M7+K8-L8) -> 975218 | O8: =N8-L8 -> 0 | Y8: =Y7+R8+S8-T8-U8-V8-W8+X8 -> 5000000 | Z8: ='TABEL INPUT'!F34 -> 0 | AD8: =AD7+AB8-AC8 -> 528915 | AF8: =AE8-AC8 -> 0 | AJ8: =AJ7+AH8-AI8 -> 376533 | AL8: =AK8-AI8 -> 0 | AS8: =AS7+AP8-AQ8+AR8 -> 208871 | AU8: =AT8-AQ8 -> 0 | AZ8: =AZ7+AW8-AY8 -> 0 | BA8: =AX8-AY8 -> 0 | BC8: DATA | BD8: ='TABEL INPUT'!F45 -> 0 | BG8: =SUM(BD8:BF8) -> 0
H9: =H8+E9-G9 -> 341717 | I9: =F9-G9 -> 0 | M9: =SUM(M8+K9-L9) -> 975218 | O9: =N9-L9 -> 0 | Y9: =Y8+R9+S9-T9-U9-V9-W9+X9 -> 5000000 | Z9: ='TABEL INPUT'!F35 -> 0 | AD9: =AD8+AB9-AC9 -> 528915 | AF9: =AE9-AC9 -> 0 | AJ9: =AJ8+AH9-AI9 -> 376533 | AL9: =AK9-AI9 -> 0 | AO9: 0 | AS9: =AS8+AP9-AQ9+AR9 -> 208871 | AU9: =AT9-AQ9 -> 0 | AZ9: =AZ8+AW9-AY9 -> 0 | BA9: =AX9-AY9 -> 0 | BC9: AIR GALON | BD9: ='TABEL INPUT'!F46 -> 0 | BG9: =SUM(BD9:BF9) -> 0
H10: =H9+E10-G10 -> 341717 | I10: =F10-G10 -> 0 | M10: =SUM(M9+K10-L10) -> 975218 | O10: =N10-L10 -> 0 | Y10: =Y9+R10+S10-T10-U10-V10-W10+X10 -> 5000000 | Z10: ='TABEL INPUT'!F36 -> 0 | AD10: =AD9+AB10-AC10 -> 528915 | AF10: =AE10-AC10 -> 0 | AJ10: =AJ9+AH10-AI10 -> 376533 | AL10: =AK10-AI10 -> 0 | AS10: =AS9+AP10-AQ10+AR10 -> 208871 | AU10: =AT10-AQ10 -> 0 | AZ10: =AZ9+AW10-AY10 -> 0 | BA10: =AX10-AY10 -> 0 | BC10: LISTRIK | BD10: ='TABEL INPUT'!F47 -> 0 | BG10: =SUM(BD10:BF10) -> 0
H11: =H10+E11-G11 -> 341717 | I11: =F11-G11 -> 0 | M11: =SUM(M10+K11-L11) -> 975218 | O11: =N11-L11 -> 0 | Y11: =Y10+R11+S11-T11-U11-V11-W11+X11 -> 5000000 | Z11: ='TABEL INPUT'!F37 -> 0 | AD11: =AD10+AB11-AC11 -> 528915 | AF11: =AE11-AC11 -> 0 | AJ11: =AJ10+AH11-AI11 -> 376533 | AL11: =AK11-AI11 -> 0 | AS11: =AS10+AP11-AQ11+AR11 -> 208871 | AU11: =AT11-AQ11 -> 0 | AZ11: =AZ10+AW11-AY11 -> 0 | BA11: =AX11-AY11 -> 0 | BC11: GAJI KARYAWAN | BD11: ='TABEL INPUT'!F48 -> 0 | BG11: =SUM(BD11:BF11) -> 0
H12: =H11+E12-G12 -> 341717 | I12: =F12-G12 -> 0 | M12: =SUM(M11+K12-L12) -> 975218 | O12: =N12-L12 -> 0 | Y12: =Y11+R12+S12-T12-U12-V12-W12+X12 -> 5000000 | Z12: ='TABEL INPUT'!F38 -> 0 | AD12: =AD11+AB12-AC12 -> 528915 | AF12: =AE12-AC12 -> 0 | AJ12: =AJ11+AH12-AI12 -> 376533 | AL12: =AK12-AI12 -> 0 | AS12: =AS11+AP12-AQ12+AR12 -> 208871 | AU12: =AT12-AQ12 -> 0 | AZ12: =AZ11+AW12-AY12 -> 0 | BA12: =AX12-AY12 -> 0 | BC12: ELINK | BD12: ='TABEL INPUT'!F49 -> 0 | BG12: =SUM(BD12:BF12) -> 0
H13: =H12+E13-G13 -> 341717 | I13: =F13-G13 -> 0 | M13: =SUM(M12+K13-L13) -> 975218 | O13: =N13-L13 -> 0 | Y13: =Y12+R13+S13-T13-U13-V13-W13+X13 -> 5000000 | AD13: =AD12+AB13-AC13 -> 528915 | AF13: =AE13-AC13 -> 0 | AJ13: =AJ12+AH13-AI13 -> 376533 | AL13: =AK13-AI13 -> 0 | AS13: =AS12+AP13-AQ13+AR13 -> 208871 | AU13: =AT13-AQ13 -> 0 | AZ13: =AZ12+AW13-AY13 -> 0 | BA13: =AX13-AY13 -> 0 | BC13: SEWA TEMPAT | BD13: ='TABEL INPUT'!F50 -> 0 | BG13: =SUM(BD13:BF13) -> 0
H14: =H13+E14-G14 -> 341717 | I14: =F14-G14 -> 0 | M14: =SUM(M13+K14-L14) -> 975218 | O14: =N14-L14 -> 0 | Y14: =Y13+R14+S14-T14-U14-V14-W14+X14 -> 5000000 | AD14: =AD13+AB14-AC14 -> 528915 | AF14: =AE14-AC14 -> 0 | AJ14: =AJ13+AH14-AI14 -> 376533 | AL14: =AK14-AI14 -> 0 | AS14: =AS13+AP14-AQ14+AR14 -> 208871 | AU14: =AT14-AQ14 -> 0 | AZ14: =AZ13+AW14-AY14 -> 0 | BA14: =AX14-AY14 -> 0 | BC14: LAINNYA | BD14: ='TABEL INPUT'!F52 -> 0 | BG14: =SUM(BD14:BF14) -> 0
H15: =H14+E15-G15 -> 341717 | I15: =F15-G15 -> 0 | M15: =SUM(M14+K15-L15) -> 975218 | O15: =N15-L15 -> 0 | Y15: =Y14+R15+S15-T15-U15-V15-W15+X15 -> 5000000 | AD15: =AD14+AB15-AC15 -> 528915 | AF15: =AE15-AC15 -> 0 | AJ15: =AJ14+AH15-AI15 -> 376533 | AL15: =AK15-AI15 -> 0 | AS15: =AS14+AP15-AQ15+AR15 -> 208871 | AU15: =AT15-AQ15 -> 0 | AZ15: =AZ14+AW15-AY15 -> 0 | BA15: =AX15-AY15 -> 0
H16: =H15+E16-G16 -> 341717 | I16: =F16-G16 -> 0 | M16: =SUM(M15+K16-L16) -> 975218 | O16: =N16-L16 -> 0 | Y16: =Y15+R16+S16-T16-U16-V16-W16+X16 -> 5000000 | AD16: =AD15+AB16-AC16 -> 528915 | AF16: =AE16-AC16 -> 0 | AJ16: =AJ15+AH16-AI16 -> 376533 | AL16: =AK16-AI16 -> 0 | AS16: =AS15+AP16-AQ16+AR16 -> 208871 | AU16: =AT16-AQ16 -> 0 | AZ16: =AZ15+AW16-AY16 -> 0 | BA16: =AX16-AY16 -> 0 | BC16: TOTAL | BD16: =BG6+BG7+BG8+BG9+BG10+BG11+BG12+BG13+BG14 -> 0
H17: =H16+E17-G17 -> 341717 | I17: =F17-G17 -> 0 | M17: =SUM(M16+K17-L17) -> 975218 | O17: =N17-L17 -> 0 | Y17: =Y16+R17+S17-T17-U17-V17-W17+X17 -> 5000000 | AD17: =AD16+AB17-AC17 -> 528915 | AF17: =AE17-AC17 -> 0 | AJ17: =AJ16+AH17-AI17 -> 376533 | AL17: =AK17-AI17 -> 0 | AS17: =AS16+AP17-AQ17+AR17 -> 208871 | AU17: =AT17-AQ17 -> 0 | AZ17: =AZ16+AW17-AY17 -> 0 | BA17: =AX17-AY17 -> 0
H18: =H17+E18-G18 -> 341717 | I18: =F18-G18 -> 0 | M18: =SUM(M17+K18-L18) -> 975218 | O18: =N18-L18 -> 0 | Y18: =Y17+R18+S18-T18-U18-V18-W18+X18 -> 5000000 | AD18: =AD17+AB18-AC18 -> 528915 | AF18: =AE18-AC18 -> 0 | AJ18: =AJ17+AH18-AI18 -> 376533 | AL18: =AK18-AI18 -> 0 | AS18: =AS17+AP18-AQ18+AR18 -> 208871 | AU18: =AT18-AQ18 -> 0 | AZ18: =AZ17+AW18-AY18 -> 0 | BA18: =AX18-AY18 -> 0
H19: =H18+E19-G19 -> 341717 | I19: =F19-G19 -> 0 | M19: =SUM(M18+K19-L19) -> 975218 | O19: =N19-L19 -> 0 | Y19: =Y18+R19+S19-T19-U19-V19-W19+X19 -> 5000000 | AD19: =AD18+AB19-AC19 -> 528915 | AF19: =AE19-AC19 -> 0 | AJ19: =AJ18+AH19-AI19 -> 376533 | AL19: =AK19-AI19 -> 0 | AS19: =AS18+AP19-AQ19+AR19 -> 208871 | AU19: =AT19-AQ19 -> 0 | AZ19: =AZ18+AW19-AY19 -> 0 | BA19: =AX19-AY19 -> 0
H20: =H19+E20-G20 -> 341717 | I20: =F20-G20 -> 0 | M20: =SUM(M19+K20-L20) -> 975218 | O20: =N20-L20 -> 0 | Y20: =Y19+R20+S20-T20-U20-V20-W20+X20 -> 5000000 | AD20: =AD19+AB20-AC20 -> 528915 | AF20: =AE20-AC20 -> 0 | AJ20: =AJ19+AH20-AI20 -> 376533 | AL20: =AK20-AI20 -> 0 | AS20: =AS19+AP20-AQ20+AR20 -> 208871 | AU20: =AT20-AQ20 -> 0 | AZ20: =AZ19+AW20-AY20 -> 0 | BA20: =AX20-AY20 -> 0
H21: =H20+E21-G21 -> 341717 | I21: =F21-G21 -> 0 | M21: =SUM(M20+K21-L21) -> 975218 | O21: =N21-L21 -> 0 | Y21: =Y20+R21+S21-T21-U21-V21-W21+X21 -> 5000000 | AD21: =AD20+AB21-AC21 -> 528915 | AF21: =AE21-AC21 -> 0 | AJ21: =AJ20+AH21-AI21 -> 376533 | AL21: =AK21-AI21 -> 0 | AS21: =AS20+AP21-AQ21+AR21 -> 208871 | AU21: =AT21-AQ21 -> 0 | AZ21: =AZ20+AW21-AY21 -> 0 | BA21: =AX21-AY21 -> 0
H22: =H21+E22-G22 -> 341717 | I22: =F22-G22 -> 0 | M22: =SUM(M21+K22-L22) -> 975218 | O22: =N22-L22 -> 0 | Y22: =Y21+R22+S22-T22-U22-V22-W22+X22 -> 5000000 | AD22: =AD21+AB22-AC22 -> 528915 | AF22: =AE22-AC22 -> 0 | AJ22: =AJ21+AH22-AI22 -> 376533 | AL22: =AK22-AI22 -> 0 | AS22: =AS21+AP22-AQ22+AR22 -> 208871 | AU22: =AT22-AQ22 -> 0 | AZ22: =AZ21+AW22-AY22 -> 0 | BA22: =AX22-AY22 -> 0
H23: =H22+E23-G23 -> 341717 | I23: =F23-G23 -> 0 | M23: =SUM(M22+K23-L23) -> 975218 | O23: =N23-L23 -> 0 | Y23: =Y22+R23+S23-T23-U23-V23-W23+X23 -> 5000000 | AD23: =AD22+AB23-AC23 -> 528915 | AF23: =AE23-AC23 -> 0 | AJ23: =AJ22+AH23-AI23 -> 376533 | AL23: =AK23-AI23 -> 0 | AS23: =AS22+AP23-AQ23+AR23 -> 208871 | AU23: =AT23-AQ23 -> 0 | AZ23: =AZ22+AW23-AY23 -> 0 | BA23: =AX23-AY23 -> 0
H24: =H23+E24-G24 -> 341717 | I24: =F24-G24 -> 0 | M24: =SUM(M23+K24-L24) -> 975218 | O24: =N24-L24 -> 0 | Y24: =Y23+R24+S24-T24-U24-V24-W24+X24 -> 5000000 | AD24: =AD23+AB24-AC24 -> 528915 | AF24: =AE24-AC24 -> 0 | AJ24: =AJ23+AH24-AI24 -> 376533 | AL24: =AK24-AI24 -> 0 | AS24: =AS23+AP24-AQ24+AR24 -> 208871 | AU24: =AT24-AQ24 -> 0 | AZ24: =AZ23+AW24-AY24 -> 0 | BA24: =AX24-AY24 -> 0
H25: =H24+E25-G25 -> 341717 | I25: =F25-G25 -> 0 | M25: =SUM(M24+K25-L25) -> 975218 | O25: =N25-L25 -> 0 | Y25: =Y24+R25+S25-T25-U25-V25-W25+X25 -> 5000000 | AD25: =AD24+AB25-AC25 -> 528915 | AF25: =AE25-AC25 -> 0 | AJ25: =AJ24+AH25-AI25 -> 376533 | AL25: =AK25-AI25 -> 0 | AS25: =AS24+AP25-AQ25+AR25 -> 208871 | AU25: =AT25-AQ25 -> 0 | AZ25: =AZ24+AW25-AY25 -> 0 | BA25: =AX25-AY25 -> 0
H26: =H25+E26-G26 -> 341717 | I26: =F26-G26 -> 0 | M26: =SUM(M25+K26-L26) -> 975218 | O26: =N26-L26 -> 0 | Y26: =Y25+R26+S26-T26-U26-V26-W26+X26 -> 5000000 | AD26: =AD25+AB26-AC26 -> 528915 | AF26: =AE26-AC26 -> 0 | AJ26: =AJ25+AH26-AI26 -> 376533 | AL26: =AK26-AI26 -> 0 | AS26: =AS25+AP26-AQ26+AR26 -> 208871 | AU26: =AT26-AQ26 -> 0 | AZ26: =AZ25+AW26-AY26 -> 0 | BA26: =AX26-AY26 -> 0
H27: =H26+E27-G27 -> 341717 | I27: =F27-G27 -> 0 | M27: =SUM(M26+K27-L27) -> 975218 | O27: =N27-L27 -> 0 | Y27: =Y26+R27+S27-T27-U27-V27-W27+X27 -> 5000000 | AD27: =AD26+AB27-AC27 -> 528915 | AF27: =AE27-AC27 -> 0 | AJ27: =AJ26+AH27-AI27 -> 376533 | AL27: =AK27-AI27 -> 0 | AS27: =AS26+AP27-AQ27+AR27 -> 208871 | AU27: =AT27-AQ27 -> 0 | AZ27: =AZ26+AW27-AY27 -> 0 | BA27: =AX27-AY27 -> 0
H28: =H27+E28-G28 -> 341717 | I28: =F28-G28 -> 0 | M28: =SUM(M27+K28-L28) -> 975218 | O28: =N28-L28 -> 0 | Y28: =Y27+R28+S28-T28-U28-V28-W28+X28 -> 5000000 | AD28: =AD27+AB28-AC28 -> 528915 | AF28: =AE28-AC28 -> 0 | AJ28: =AJ27+AH28-AI28 -> 376533 | AL28: =AK28-AI28 -> 0 | AS28: =AS27+AP28-AQ28+AR28 -> 208871 | AU28: =AT28-AQ28 -> 0 | AZ28: =AZ27+AW28-AY28 -> 0 | BA28: =AX28-AY28 -> 0
... H190: =H189+E190-G190 -> 341717 | I190: =F190-G190 -> 0 | M190: =SUM(M189+K190-L190) -> 975218 | O190: =N190-L190 -> 0 | Y190: =Y189+R190+S190-T190-U190-V190-W190+X190 -> 5000000 | AD190: =AD189+AB190-AC190 -> 528915 | AF190: =AE190-AC190 -> 0 | AJ190: =AJ189+AH190-AI190 -> 376533 | AL190: =AK190-AI190 -> 0 | AS190: =AS189+AP190-AQ190+AR190 -> 208871 | AU190: =AT190-AQ190 -> 0 | AZ190: =AZ189+AW190-AY190 -> 0 | BA190: =AX190-AY190 -> 0
I191: =SUM(I6:I190) -> 0 | O191: =SUM(O6:O190) -> 0 | W191: =SUM(W6:W190) -> 0 | X191: =SUM(X6:X190) -> 0 | Z191: =SUM(Z6:Z190) -> 0 | AF191: =SUM(AF6:AF190) -> 0 | AL191: =SUM(AL6:AL190) -> 0 | AR191: =SUM(AR6:AR190) -> 0 | AU191: =SUM(AU6:AU190) -> 0 | BA191: =SUM(BA6:BA190) -> 0
AZ193: PROFIT | BA193: =I191+O191+X191+Z191+AF191+AL191+AR191+AU191+BA191 -> 0
E197: DIGI POS | K197: EDC FASTPAY | R197: BRIMO C1 | AB197: 3 SAKTI | AH197: RITA PPOB | AP197: PEGADAIAN | AW197: SIDOMPUL

Sheet AGEN HABIBOLA
A3: DIGIPOS | H3: FAST PAY | N3: PEGADAIAN | U3: BRIMO | AA3: BNI | AG3: BCA | AM3: MANDIRI | AS3: BPD NTT
A4: O85191401601 FRANSISKA MARGARETHA | H4: FA391817 FRANSISKA MARGARETHA PRADA | N4: O85191401601 MARIA MAGDALENA | U4: ALDOPUS YOMANSIUS BURA 0119 0101 1019 532 | AA4: SEFTIANUS RUBEN 1110203088 | AG4: SEFTIANUS RUBEN 6986084102 | AM4: SEFTIANUS RUBEN 1810003483022 | AS4: SEFTIANUS RUBEN 2511214109
A5: TOP UP | B5: HARGA JUAL | C5: HARGA MODAL | D5: SALDO | E5: BIAYA | H5: TARIK / TOP UP | I5: TRANSFER KELUAR | J5: SALDO | K5: HARGA JUAL | L5: BIAYA | N5: TOP UP | O5: TRANSFER KELUAR | P5: FEE | Q5: SALDO | R5: HARGA BAYAR | S5: BIAYA | U5: TRANSFER MASUK | V5: TRANSFER KELUAR | W5: BIAYA ADMIN BANK | X5: SALDO | Y5: BIAYA | AA5: TRANSFER MASUK | AB5: TRANSFER KELUAR | AC5: ADMIN BANK | AD5: SALDO | AE5: BIAYA | AG5: TRANSFER MASUK | AH5: TRANSFER KELUAR | AI5: ADMIN BANK | AJ5: SALDO | AK5: BIAYA | AM5: TRANSFER MASUK | AN5: TRANSFER KELUAR | AO5: ADMIN BANK | AP5: SALDO | AQ5: BIAYA | AS5: TRANSFER MASUK | AT5: TRANSFER KELUAR | AU5: ADMIN BANK | AV5: SALDO | AW5: BIAYA
D6: ='TABEL INPUT'!I5 -> 856669 | J6: ='TABEL INPUT'!I11 -> 36916 | Q6: ='TABEL INPUT'!I12 -> 159814 | X6: ='TABEL INPUT'!I6 -> 26290 | AD6: ='TABEL INPUT'!I7 -> 21907 | AJ6: ='TABEL INPUT'!I8 -> 82000 | AP6: ='TABEL INPUT'!I9 -> 46000 | AV6: ='TABEL INPUT'!I10 -> 69862 | AY6: PENGELUARAN
D7: =D6+A7-C7 -> 856669 | E7: =B7-C7 -> 0 | J7: =J6+H7-I7 -> 36916 | L7: =K7-I7 -> 0 | Q7: =Q6+N7-O7+P7 -> 159814 | S7: =R7-O7+P7 -> 0 | X7: =X6+U7-V7-W7 -> 26290 | Y7: ='TABEL INPUT'!I32 -> 0 | AD7: =AD6+AA7-AB7-AC7 -> 21907 | AJ7: =AJ6+AG7-AH7-AI7 -> 82000 | AP7: =AP6+AM7-AN7-AO7 -> 46000 | AV7: =AV6+AS7-AT7-AU7 -> 69862 | AY7: BIAYA TOP UP / TARIK | AZ7: ='TABEL INPUT'!I43 -> 0 | BC7: =SUM(AZ7:BB7) -> 0
D8: =D7+A8-C8 -> 856669 | E8: =B8-C8 -> 0 | J8: =J7+H8-I8 -> 36916 | L8: =K8-I8 -> 0 | Q8: =Q7+N8-O8+P8 -> 159814 | S8: =R8-O8+P8 -> 0 | X8: =X7+U8-V8-W8 -> 26290 | Y8: ='TABEL INPUT'!I33 -> 0 | AD8: =AD7+AA8-AB8-AC8 -> 21907 | AJ8: =AJ7+AG8-AH8-AI8 -> 82000 | AP8: =AP7+AM8-AN8-AO8 -> 46000 | AV8: =AV7+AS8-AT8-AU8 -> 69862 | AY8: ADMIN BULANAN | AZ8: ='TABEL INPUT'!I44 -> 0 | BC8: =SUM(AZ8:BB8) -> 0
D9: =D8+A9-C9 -> 856669 | E9: =B9-C9 -> 0 | J9: =J8+H9-I9 -> 36916 | L9: =K9-I9 -> 0 | Q9: =Q8+N9-O9+P9 -> 159814 | S9: =R9-O9+P9 -> 0 | X9: =X8+U9-V9-W9 -> 26290 | Y9: ='TABEL INPUT'!I34 -> 0 | AD9: =AD8+AA9-AB9-AC9 -> 21907 | AJ9: =AJ8+AG9-AH9-AI9 -> 82000 | AP9: =AP8+AM9-AN9-AO9 -> 46000 | AV9: =AV8+AS9-AT9-AU9 -> 69862 | AY9: DATA | AZ9: ='TABEL INPUT'!I45 -> 0 | BC9: =SUM(AZ9:BB9) -> 0
D10: =D9+A10-C10 -> 856669 | E10: =B10-C10 -> 0 | J10: =J9+H10-I10 -> 36916 | L10: =K10-I10 -> 0 | Q10: =Q9+N10-O10+P10 -> 159814 | S10: =R10-O10+P10 -> 0 | X10: =X9+U10-V10-W10 -> 26290 | Y10: ='TABEL INPUT'!I35 -> 0 | AD10: =AD9+AA10-AB10-AC10 -> 21907 | AJ10: =AJ9+AG10-AH10-AI10 -> 82000 | AP10: =AP9+AM10-AN10-AO10 -> 46000 | AV10: =AV9+AS10-AT10-AU10 -> 69862 | AY10: AIR GALON | AZ10: ='TABEL INPUT'!I46 -> 0 | BC10: =SUM(AZ10:BB10) -> 0
D11: =D10+A11-C11 -> 856669 | E11: =B11-C11 -> 0 | J11: =J10+H11-I11 -> 36916 | L11: =K11-I11 -> 0 | Q11: =Q10+N11-O11+P11 -> 159814 | S11: =R11-O11+P11 -> 0 | X11: =X10+U11-V11-W11 -> 26290 | Y11: ='TABEL INPUT'!I36 -> 0 | AD11: =AD10+AA11-AB11-AC11 -> 21907 | AJ11: =AJ10+AG11-AH11-AI11 -> 82000 | AP11: =AP10+AM11-AN11-AO11 -> 46000 | AV11: =AV10+AS11-AT11-AU11 -> 69862 | AY11: LISTRIK | AZ11: ='TABEL INPUT'!I47 -> 0 | BC11: =SUM(AZ11:BB11) -> 0
D12: =D11+A12-C12 -> 856669 | E12: =B12-C12 -> 0 | J12: =J11+H12-I12 -> 36916 | L12: =K12-I12 -> 0 | Q12: =Q11+N12-O12+P12 -> 159814 | S12: =R12-O12+P12 -> 0 | X12: =X11+U12-V12-W12 -> 26290 | Y12: ='TABEL INPUT'!I37 -> 0 | AD12: =AD11+AA12-AB12-AC12 -> 21907 | AJ12: =AJ11+AG12-AH12-AI12 -> 82000 | AP12: =AP11+AM12-AN12-AO12 -> 46000 | AV12: =AV11+AS12-AT12-AU12 -> 69862 | AY12: GAJI KARYAWAN | AZ12: ='TABEL INPUT'!I48 -> 0 | BC12: =SUM(AZ12:BB12) -> 0
D13: =D12+A13-C13 -> 856669 | E13: =B13-C13 -> 0 | J13: =J12+H13-I13 -> 36916 | L13: =K13-I13 -> 0 | Q13: =Q12+N13-O13+P13 -> 159814 | S13: =R13-O13+P13 -> 0 | X13: =X12+U13-V13-W13 -> 26290 | Y13: ='TABEL INPUT'!I38 -> 0 | AD13: =AD12+AA13-AB13-AC13 -> 21907 | AJ13: =AJ12+AG13-AH13-AI13 -> 82000 | AP13: =AP12+AM13-AN13-AO13 -> 46000 | AV13: =AV12+AS13-AT13-AU13 -> 69862 | AY13: ELINK | AZ13: ='TABEL INPUT'!I49 -> 0 | BC13: =SUM(AZ13:BB13) -> 0
D14: =D13+A14-C14 -> 856669 | E14: =B14-C14 -> 0 | J14: =J13+H14-I14 -> 36916 | L14: =K14-I14 -> 0 | Q14: =Q13+N14-O14+P14 -> 159814 | S14: =R14-O14+P14 -> 0 | X14: =X13+U14-V14-W14 -> 26290 | AD14: =AD13+AA14-AB14-AC14 -> 21907 | AJ14: =AJ13+AG14-AH14-AI14 -> 82000 | AP14: =AP13+AM14-AN14-AO14 -> 46000 | AV14: =AV13+AS14-AT14-AU14 -> 69862 | AY14: SEWA TEMPAT | AZ14: ='TABEL INPUT'!I50 -> 0 | BC14: =SUM(AZ14:BB14) -> 0
D15: =D14+A15-C15 -> 856669 | E15: =B15-C15 -> 0 | J15: =J14+H15-I15 -> 36916 | L15: =K15-I15 -> 0 | Q15: =Q14+N15-O15+P15 -> 159814 | S15: =R15-O15+P15 -> 0 | X15: =X14+U15-V15-W15 -> 26290 | AD15: =AD14+AA15-AB15-AC15 -> 21907 | AJ15: =AJ14+AG15-AH15-AI15 -> 82000 | AP15: =AP14+AM15-AN15-AO15 -> 46000 | AV15: =AV14+AS15-AT15-AU15 -> 69862 | AY15: LAINNYA | AZ15: ='TABEL INPUT'!I52 -> 0 | BC15: =SUM(AZ15:BB15) -> 0
D16: =D15+A16-C16 -> 856669 | E16: =B16-C16 -> 0 | J16: =J15+H16-I16 -> 36916 | L16: =K16-I16 -> 0 | Q16: =Q15+N16-O16+P16 -> 159814 | S16: =R16-O16+P16 -> 0 | X16: =X15+U16-V16-W16 -> 26290 | AD16: =AD15+AA16-AB16-AC16 -> 21907 | AJ16: =AJ15+AG16-AH16-AI16 -> 82000 | AP16: =AP15+AM16-AN16-AO16 -> 46000 | AV16: =AV15+AS16-AT16-AU16 -> 69862
D17: =D16+A17-C17 -> 856669 | E17: =B17-C17 -> 0 | J17: =J16+H17-I17 -> 36916 | L17: =K17-I17 -> 0 | Q17: =Q16+N17-O17+P17 -> 159814 | S17: =R17-O17+P17 -> 0 | X17: =X16+U17-V17-W17 -> 26290 | AD17: =AD16+AA17-AB17-AC17 -> 21907 | AJ17: =AJ16+AG17-AH17-AI17 -> 82000 | AP17: =AP16+AM17-AN17-AO17 -> 46000 | AV17: =AV16+AS17-AT17-AU17 -> 69862 | AY17: TOTAL | AZ17: =BC7+BC8+BC9+BC10+BC11+BC12+BC13+BC14+BC15 -> 0
D18: =D17+A18-C18 -> 856669 | E18: =B18-C18 -> 0 | J18: =J17+H18-I18 -> 36916 | L18: =K18-I18 -> 0 | Q18: =Q17+N18-O18+P18 -> 159814 | S18: =R18-O18+P18 -> 0 | X18: =X17+U18-V18-W18 -> 26290 | AD18: =AD17+AA18-AB18-AC18 -> 21907 | AJ18: =AJ17+AG18-AH18-AI18 -> 82000 | AP18: =AP17+AM18-AN18-AO18 -> 46000 | AV18: =AV17+AS18-AT18-AU18 -> 69862
D19: =D18+A19-C19 -> 856669 | E19: =B19-C19 -> 0 | J19: =J18+H19-I19 -> 36916 | L19: =K19-I19 -> 0 | Q19: =Q18+N19-O19+P19 -> 159814 | S19: =R19-O19+P19 -> 0 | X19: =X18+U19-V19-W19 -> 26290 | AD19: =AD18+AA19-AB19-AC19 -> 21907 | AJ19: =AJ18+AG19-AH19-AI19 -> 82000 | AP19: =AP18+AM19-AN19-AO19 -> 46000 | AV19: =AV18+AS19-AT19-AU19 -> 69862
D20: =D19+A20-C20 -> 856669 | E20: =B20-C20 -> 0 | J20: =J19+H20-I20 -> 36916 | L20: =K20-I20 -> 0 | Q20: =Q19+N20-O20+P20 -> 159814 | S20: =R20-O20+P20 -> 0 | X20: =X19+U20-V20-W20 -> 26290 | AD20: =AD19+AA20-AB20-AC20 -> 21907 | AJ20: =AJ19+AG20-AH20-AI20 -> 82000 | AP20: =AP19+AM20-AN20-AO20 -> 46000 | AV20: =AV19+AS20-AT20-AU20 -> 69862
D21: =D20+A21-C21 -> 856669 | E21: =B21-C21 -> 0 | J21: =J20+H21-I21 -> 36916 | L21: =K21-I21 -> 0 | Q21: =Q20+N21-O21+P21 -> 159814 | S21: =R21-O21+P21 -> 0 | X21: =X20+U21-V21-W21 -> 26290 | AD21: =AD20+AA21-AB21-AC21 -> 21907 | AJ21: =AJ20+AG21-AH21-AI21 -> 82000 | AP21: =AP20+AM21-AN21-AO21 -> 46000 | AV21: =AV20+AS21-AT21-AU21 -> 69862
D22: =D21+A22-C22 -> 856669 | E22: =B22-C22 -> 0 | J22: =J21+H22-I22 -> 36916 | L22: =K22-I22 -> 0 | Q22: =Q21+N22-O22+P22 -> 159814 | S22: =R22-O22+P22 -> 0 | X22: =X21+U22-V22-W22 -> 26290 | AD22: =AD21+AA22-AB22-AC22 -> 21907 | AJ22: =AJ21+AG22-AH22-AI22 -> 82000 | AP22: =AP21+AM22-AN22-AO22 -> 46000 | AV22: =AV21+AS22-AT22-AU22 -> 69862
D23: =D22+A23-C23 -> 856669 | E23: =B23-C23 -> 0 | J23: =J22+H23-I23 -> 36916 | L23: =K23-I23 -> 0 | Q23: =Q22+N23-O23+P23 -> 159814 | S23: =R23-O23+P23 -> 0 | X23: =X22+U23-V23-W23 -> 26290 | AD23: =AD22+AA23-AB23-AC23 -> 21907 | AJ23: =AJ22+AG23-AH23-AI23 -> 82000 | AP23: =AP22+AM23-AN23-AO23 -> 46000 | AV23: =AV22+AS23-AT23-AU23 -> 69862
D24: =D23+A24-C24 -> 856669 | E24: =B24-C24 -> 0 | J24: =J23+H24-I24 -> 36916 | L24: =K24-I24 -> 0 | Q24: =Q23+N24-O24+P24 -> 159814 | S24: =R24-O24+P24 -> 0 | X24: =X23+U24-V24-W24 -> 26290 | AD24: =AD23+AA24-AB24-AC24 -> 21907 | AJ24: =AJ23+AG24-AH24-AI24 -> 82000 | AP24: =AP23+AM24-AN24-AO24 -> 46000 | AV24: =AV23+AS24-AT24-AU24 -> 69862
D25: =D24+A25-C25 -> 856669 | E25: =B25-C25 -> 0 | J25: =J24+H25-I25 -> 36916 | L25: =K25-I25 -> 0 | Q25: =Q24+N25-O25+P25 -> 159814 | S25: =R25-O25+P25 -> 0 | X25: =X24+U25-V25-W25 -> 26290 | AD25: =AD24+AA25-AB25-AC25 -> 21907 | AJ25: =AJ24+AG25-AH25-AI25 -> 82000 | AP25: =AP24+AM25-AN25-AO25 -> 46000 | AV25: =AV24+AS25-AT25-AU25 -> 69862
D26: =D25+A26-C26 -> 856669 | E26: =B26-C26 -> 0 | J26: =J25+H26-I26 -> 36916 | L26: =K26-I26 -> 0 | Q26: =Q25+N26-O26+P26 -> 159814 | S26: =R26-O26+P26 -> 0 | X26: =X25+U26-V26-W26 -> 26290 | AD26: =AD25+AA26-AB26-AC26 -> 21907 | AJ26: =AJ25+AG26-AH26-AI26 -> 82000 | AP26: =AP25+AM26-AN26-AO26 -> 46000 | AV26: =AV25+AS26-AT26-AU26 -> 69862
D27: =D26+A27-C27 -> 856669 | E27: =B27-C27 -> 0 | J27: =J26+H27-I27 -> 36916 | L27: =K27-I27 -> 0 | Q27: =Q26+N27-O27+P27 -> 159814 | S27: =R27-O27+P27 -> 0 | X27: =X26+U27-V27-W27 -> 26290 | AD27: =AD26+AA27-AB27-AC27 -> 21907 | AJ27: =AJ26+AG27-AH27-AI27 -> 82000 | AP27: =AP26+AM27-AN27-AO27 -> 46000 | AV27: =AV26+AS27-AT27-AU27 -> 69862
D28: =D27+A28-C28 -> 856669 | E28: =B28-C28 -> 0 | J28: =J27+H28-I28 -> 36916 | L28: =K28-I28 -> 0 | Q28: =Q27+N28-O28+P28 -> 159814 | S28: =R28-O28+P28 -> 0 | X28: =X27+U28-V28-W28 -> 26290 | AD28: =AD27+AA28-AB28-AC28 -> 21907 | AJ28: =AJ27+AG28-AH28-AI28 -> 82000 | AP28: =AP27+AM28-AN28-AO28 -> 46000 | AV28: =AV27+AS28-AT28-AU28 -> 69862
D29: =D28+A29-C29 -> 856669 | E29: =B29-C29 -> 0 | J29: =J28+H29-I29 -> 36916 | L29: =K29-I29 -> 0 | Q29: =Q28+N29-O29+P29 -> 159814 | S29: =R29-O29+P29 -> 0 | X29: =X28+U29-V29-W29 -> 26290 | AD29: =AD28+AA29-AB29-AC29 -> 21907 | AJ29: =AJ28+AG29-AH29-AI29 -> 82000 | AP29: =AP28+AM29-AN29-AO29 -> 46000 | AV29: =AV28+AS29-AT29-AU29 -> 69862
... D191: =D190+A191-C191 -> 856669 | E191: =B191-C191 -> 0 | J191: =J190+H191-I191 -> 36916 | L191: =K191-I191 -> 0 | Q191: =Q190+N191-O191+P191 -> 159814 | S191: =R191-O191+P191 -> 0 | X191: =X190+U191-V191-W191 -> 26290 | AD191: =AD190+AA191-AB191-AC191 -> 21907 | AJ191: =AJ190+AG191-AH191-AI191 -> 82000 | AP191: =AP190+AM191-AN191-AO191 -> 46000 | AV191: =AV190+AS191-AT191-AU191 -> 69862
E192: =SUM(E7:E191) -> 0 | L192: =SUM(L7:L191) -> 0 | S192: =SUM(S7:S191) -> 0 | Y192: =SUM(Y7:Y191) -> 0 | AE192: =SUM(AE7:AE191) -> 0 | AK192: =SUM(AK7:AK191) -> 0 | AQ192: =SUM(AQ7:AQ191) -> 0 | AW192: =SUM(AW7:AW191) -> 0
AV193: PROFIT | AW193: =E192+L192+S192+Y192+AE192+AK192+AQ192+AW192 -> 0
A198: DIGIPOS | H198: FAST PAY | N198: PEGADAIAN | U198: BRIMO | AA198: SANROY JUNIOR | AG198: BRIMO T2 | AM198: BNI THYAND | AS198: BNI THYAND

Sheet AGEN WATUBLAPI
B3: DIGIPOS R2 WATUBLAPI 085189220661 | H3: EDC FRANSISKA MARGARETHA FA391817 | O3: BRILINK THYAND BARU 469301000223502 | Y3: 3 SAKTI CHYKA 08999977283 | AE3: SIMPEL IM3 085702789843 | AM3: PEGADAIAN CHYKA + 2437 | AT3: SIDOMPUL 087788625894
B4: TOP UP | C4: HARGA JUAL | D4: HARGA MODAL | E4: SALDO | F4: BIAYA | H4: TARIK / TOP UP | I4: TRANSFER | J4: SALDO | K4: HARGA JUAL | L4: BIAYA | O4: TOP UP | P4: TARIK TUNAI | Q4: BRIMO KELUAR | R4: TRANSFER BRI | S4: LAINNYA | T4: ADMIN BANK | U4: FEE | V4: SALDO | W4: BIAYA | Y4: TARIK / TOP UP | Z4: TRANSFER | AA4: SALDO | AB4: HARGA JUAL | AC4: BIAYA | AE4: TARIK / TOP UP | AF4: TRANSFER | AG4: SALDO | AH4: HARGA JUAL | AI4: BIAYA | AM4: TOP UP | AN4: TRANSFER KELUAR | AO4: KOMISI | AP4: SALDO | AQ4: HARGA BAYAR | AR4: BIAYA | AT4: TOP UP | AU4: JUAL PULSA | AV4: HARGA MODAL | AW4: SALDO | AX4: BIAYA
E5: ='TABEL INPUT'!L5 -> 140185 | J5: ='TABEL INPUT'!L10 -> 1066262 | L5: =K5-I5 -> 0 | V5: ='TABEL INPUT'!L4 -> 5000000 | AA5: ='TABEL INPUT'!L7 -> 202452 | AC5: =AB5-Z5 -> 0 | AG5: ='TABEL INPUT'!L8 -> 466700 | AI5: =AH5-AF5 -> 0 | AP5: ='TABEL INPUT'!L9 -> 827481 | AR5: =AQ5-AN5 -> 0 | AW5: 0 | AZ5: PENGELUARAN
E6: =E5+B6-D6 -> 140185 | F6: =C6-D6 -> 0 | J6: =SUM(J5+H6-I6) -> 1066262 | L6: =K6-I6 -> 0 | V6: =V5+O6+P6-Q6-R6-S6-T6+U6 -> 5000000 | W6: ='TABEL INPUT'!L32 -> 0 | AA6: =AA5+Y6-Z6 -> 202452 | AC6: =AB6-Z6 -> 0 | AG6: =AG5+AE6-AF6 -> 466700 | AI6: =AH6-AF6 -> 0 | AP6: =AP5+AM6-AN6+AO6 -> 827481 | AR6: =AQ6-AN6 -> 0 | AW6: =AW5+AT6-AV6 -> 0 | AX6: =AU6-AV6 -> 0 | AZ6: BIAYA TOP UP | BA6: ='TABEL INPUT'!L43 -> 0 | BD6: =SUM(BA6:BC6) -> 0
E7: =E6+B7-D7 -> 140185 | F7: =C7-D7 -> 0 | J7: =SUM(J6+H7-I7) -> 1066262 | L7: =K7-I7 -> 0 | V7: =V6+O7+P7-Q7-R7-S7-T7+U7 -> 5000000 | W7: ='TABEL INPUT'!L33 -> 0 | AA7: =AA6+Y7-Z7 -> 202452 | AC7: =AB7-Z7 -> 0 | AG7: =AG6+AE7-AF7 -> 466700 | AI7: =AH7-AF7 -> 0 | AP7: =AP6+AM7-AN7+AO7 -> 827481 | AR7: =AQ7-AN7 -> 0 | AW7: =AW6+AT7-AV7 -> 0 | AX7: =AU7-AV7 -> 0 | AZ7: ADMIN BULANAN | BA7: ='TABEL INPUT'!L44 -> 0 | BD7: =SUM(BA7:BC7) -> 0
E8: =E7+B8-D8 -> 140185 | F8: =C8-D8 -> 0 | J8: =SUM(J7+H8-I8) -> 1066262 | L8: =K8-I8 -> 0 | V8: =V7+O8+P8-Q8-R8-S8-T8+U8 -> 5000000 | W8: ='TABEL INPUT'!L34 -> 0 | AA8: =AA7+Y8-Z8 -> 202452 | AC8: =AB8-Z8 -> 0 | AG8: =AG7+AE8-AF8 -> 466700 | AI8: =AH8-AF8 -> 0 | AP8: =AP7+AM8-AN8+AO8 -> 827481 | AR8: =AQ8-AN8 -> 0 | AW8: =AW7+AT8-AV8 -> 0 | AX8: =AU8-AV8 -> 0 | AZ8: DATA | BA8: ='TABEL INPUT'!L45 -> 0 | BD8: =SUM(BA8:BC8) -> 0
E9: =E8+B9-D9 -> 140185 | F9: =C9-D9 -> 0 | J9: =SUM(J8+H9-I9) -> 1066262 | L9: =K9-I9 -> 0 | V9: =V8+O9+P9-Q9-R9-S9-T9+U9 -> 5000000 | W9: ='TABEL INPUT'!L35 -> 0 | AA9: =AA8+Y9-Z9 -> 202452 | AC9: =AB9-Z9 -> 0 | AG9: =AG8+AE9-AF9 -> 466700 | AI9: =AH9-AF9 -> 0 | AL9: 0 | AP9: =AP8+AM9-AN9+AO9 -> 827481 | AR9: =AQ9-AN9 -> 0 | AW9: =AW8+AT9-AV9 -> 0 | AX9: =AU9-AV9 -> 0 | AZ9: AIR GALON | BA9: ='TABEL INPUT'!L46 -> 0 | BD9: =SUM(BA9:BC9) -> 0
E10: =E9+B10-D10 -> 140185 | F10: =C10-D10 -> 0 | J10: =SUM(J9+H10-I10) -> 1066262 | L10: =K10-I10 -> 0 | V10: =V9+O10+P10-Q10-R10-S10-T10+U10 -> 5000000 | W10: ='TABEL INPUT'!L36 -> 0 | AA10: =AA9+Y10-Z10 -> 202452 | AC10: =AB10-Z10 -> 0 | AG10: =AG9+AE10-AF10 -> 466700 | AI10: =AH10-AF10 -> 0 | AP10: =AP9+AM10-AN10+AO10 -> 827481 | AR10: =AQ10-AN10 -> 0 | AW10: =AW9+AT10-AV10 -> 0 | AX10: =AU10-AV10 -> 0 | AZ10: LISTRIK | BA10: ='TABEL INPUT'!L47 -> 0 | BD10: =SUM(BA10:BC10) -> 0
E11: =E10+B11-D11 -> 140185 | F11: =C11-D11 -> 0 | J11: =SUM(J10+H11-I11) -> 1066262 | L11: =K11-I11 -> 0 | V11: =V10+O11+P11-Q11-R11-S11-T11+U11 -> 5000000 | W11: ='TABEL INPUT'!L37 -> 0 | AA11: =AA10+Y11-Z11 -> 202452 | AC11: =AB11-Z11 -> 0 | AG11: =AG10+AE11-AF11 -> 466700 | AI11: =AH11-AF11 -> 0 | AP11: =AP10+AM11-AN11+AO11 -> 827481 | AR11: =AQ11-AN11 -> 0 | AW11: =AW10+AT11-AV11 -> 0 | AX11: =AU11-AV11 -> 0 | AZ11: GAJI KARYAWAN | BA11: ='TABEL INPUT'!L48 -> 0 | BD11: =SUM(BA11:BC11) -> 0
E12: =E11+B12-D12 -> 140185 | F12: =C12-D12 -> 0 | J12: =SUM(J11+H12-I12) -> 1066262 | L12: =K12-I12 -> 0 | V12: =V11+O12+P12-Q12-R12-S12-T12+U12 -> 5000000 | W12: ='TABEL INPUT'!L38 -> 0 | AA12: =AA11+Y12-Z12 -> 202452 | AC12: =AB12-Z12 -> 0 | AG12: =AG11+AE12-AF12 -> 466700 | AI12: =AH12-AF12 -> 0 | AP12: =AP11+AM12-AN12+AO12 -> 827481 | AR12: =AQ12-AN12 -> 0 | AW12: =AW11+AT12-AV12 -> 0 | AX12: =AU12-AV12 -> 0 | AZ12: ELINK | BA12: ='TABEL INPUT'!L49 -> 0 | BD12: =SUM(BA12:BC12) -> 0
E13: =E12+B13-D13 -> 140185 | F13: =C13-D13 -> 0 | J13: =SUM(J12+H13-I13) -> 1066262 | L13: =K13-I13 -> 0 | V13: =V12+O13+P13-Q13-R13-S13-T13+U13 -> 5000000 | AA13: =AA12+Y13-Z13 -> 202452 | AC13: =AB13-Z13 -> 0 | AG13: =AG12+AE13-AF13 -> 466700 | AI13: =AH13-AF13 -> 0 | AP13: =AP12+AM13-AN13+AO13 -> 827481 | AR13: =AQ13-AN13 -> 0 | AW13: =AW12+AT13-AV13 -> 0 | AX13: =AU13-AV13 -> 0 | AZ13: SEWA TEMPAT | BA13: ='TABEL INPUT'!L50 -> 0 | BD13: =SUM(BA13:BC13) -> 0
E14: =E13+B14-D14 -> 140185 | F14: =C14-D14 -> 0 | J14: =SUM(J13+H14-I14) -> 1066262 | L14: =K14-I14 -> 0 | V14: =V13+O14+P14-Q14-R14-S14-T14+U14 -> 5000000 | AA14: =AA13+Y14-Z14 -> 202452 | AC14: =AB14-Z14 -> 0 | AG14: =AG13+AE14-AF14 -> 466700 | AI14: =AH14-AF14 -> 0 | AP14: =AP13+AM14-AN14+AO14 -> 827481 | AR14: =AQ14-AN14 -> 0 | AW14: =AW13+AT14-AV14 -> 0 | AX14: =AU14-AV14 -> 0 | AZ14: LAINNYA | BA14: ='TABEL INPUT'!L52 -> 0 | BD14: =SUM(BA14:BC14) -> 0
E15: =E14+B15-D15 -> 140185 | F15: =C15-D15 -> 0 | J15: =SUM(J14+H15-I15) -> 1066262 | L15: =K15-I15 -> 0 | V15: =V14+O15+P15-Q15-R15-S15-T15+U15 -> 5000000 | AA15: =AA14+Y15-Z15 -> 202452 | AC15: =AB15-Z15 -> 0 | AG15: =AG14+AE15-AF15 -> 466700 | AI15: =AH15-AF15 -> 0 | AP15: =AP14+AM15-AN15+AO15 -> 827481 | AR15: =AQ15-AN15 -> 0 | AW15: =AW14+AT15-AV15 -> 0 | AX15: =AU15-AV15 -> 0
E16: =E15+B16-D16 -> 140185 | F16: =C16-D16 -> 0 | J16: =SUM(J15+H16-I16) -> 1066262 | L16: =K16-I16 -> 0 | V16: =V15+O16+P16-Q16-R16-S16-T16+U16 -> 5000000 | AA16: =AA15+Y16-Z16 -> 202452 | AC16: =AB16-Z16 -> 0 | AG16: =AG15+AE16-AF16 -> 466700 | AI16: =AH16-AF16 -> 0 | AP16: =AP15+AM16-AN16+AO16 -> 827481 | AR16: =AQ16-AN16 -> 0 | AW16: =AW15+AT16-AV16 -> 0 | AX16: =AU16-AV16 -> 0 | AZ16: TOTAL | BA16: =BD6+BD7+BD8+BD9+BD10+BD11+BD12+BD13+BD14 -> 0
E17: =E16+B17-D17 -> 140185 | F17: =C17-D17 -> 0 | J17: =SUM(J16+H17-I17) -> 1066262 | L17: =K17-I17 -> 0 | V17: =V16+O17+P17-Q17-R17-S17-T17+U17 -> 5000000 | AA17: =AA16+Y17-Z17 -> 202452 | AC17: =AB17-Z17 -> 0 | AG17: =AG16+AE17-AF17 -> 466700 | AI17: =AH17-AF17 -> 0 | AP17: =AP16+AM17-AN17+AO17 -> 827481 | AR17: =AQ17-AN17 -> 0 | AW17: =AW16+AT17-AV17 -> 0 | AX17: =AU17-AV17 -> 0
E18: =E17+B18-D18 -> 140185 | F18: =C18-D18 -> 0 | J18: =SUM(J17+H18-I18) -> 1066262 | L18: =K18-I18 -> 0 | V18: =V17+O18+P18-Q18-R18-S18-T18+U18 -> 5000000 | AA18: =AA17+Y18-Z18 -> 202452 | AC18: =AB18-Z18 -> 0 | AG18: =AG17+AE18-AF18 -> 466700 | AI18: =AH18-AF18 -> 0 | AP18: =AP17+AM18-AN18+AO18 -> 827481 | AR18: =AQ18-AN18 -> 0 | AW18: =AW17+AT18-AV18 -> 0 | AX18: =AU18-AV18 -> 0
E19: =E18+B19-D19 -> 140185 | F19: =C19-D19 -> 0 | J19: =SUM(J18+H19-I19) -> 1066262 | L19: =K19-I19 -> 0 | V19: =V18+O19+P19-Q19-R19-S19-T19+U19 -> 5000000 | AA19: =AA18+Y19-Z19 -> 202452 | AC19: =AB19-Z19 -> 0 | AG19: =AG18+AE19-AF19 -> 466700 | AI19: =AH19-AF19 -> 0 | AP19: =AP18+AM19-AN19+AO19 -> 827481 | AR19: =AQ19-AN19 -> 0 | AW19: =AW18+AT19-AV19 -> 0 | AX19: =AU19-AV19 -> 0
E20: =E19+B20-D20 -> 140185 | F20: =C20-D20 -> 0 | J20: =SUM(J19+H20-I20) -> 1066262 | L20: =K20-I20 -> 0 | V20: =V19+O20+P20-Q20-R20-S20-T20+U20 -> 5000000 | AA20: =AA19+Y20-Z20 -> 202452 | AC20: =AB20-Z20 -> 0 | AG20: =AG19+AE20-AF20 -> 466700 | AI20: =AH20-AF20 -> 0 | AP20: =AP19+AM20-AN20+AO20 -> 827481 | AR20: =AQ20-AN20 -> 0 | AW20: =AW19+AT20-AV20 -> 0 | AX20: =AU20-AV20 -> 0
E21: =E20+B21-D21 -> 140185 | F21: =C21-D21 -> 0 | J21: =SUM(J20+H21-I21) -> 1066262 | L21: =K21-I21 -> 0 | V21: =V20+O21+P21-Q21-R21-S21-T21+U21 -> 5000000 | AA21: =AA20+Y21-Z21 -> 202452 | AC21: =AB21-Z21 -> 0 | AG21: =AG20+AE21-AF21 -> 466700 | AI21: =AH21-AF21 -> 0 | AP21: =AP20+AM21-AN21+AO21 -> 827481 | AR21: =AQ21-AN21 -> 0 | AW21: =AW20+AT21-AV21 -> 0 | AX21: =AU21-AV21 -> 0
E22: =E21+B22-D22 -> 140185 | F22: =C22-D22 -> 0 | J22: =SUM(J21+H22-I22) -> 1066262 | L22: =K22-I22 -> 0 | V22: =V21+O22+P22-Q22-R22-S22-T22+U22 -> 5000000 | AA22: =AA21+Y22-Z22 -> 202452 | AC22: =AB22-Z22 -> 0 | AG22: =AG21+AE22-AF22 -> 466700 | AI22: =AH22-AF22 -> 0 | AP22: =AP21+AM22-AN22+AO22 -> 827481 | AR22: =AQ22-AN22 -> 0 | AW22: =AW21+AT22-AV22 -> 0 | AX22: =AU22-AV22 -> 0
E23: =E22+B23-D23 -> 140185 | F23: =C23-D23 -> 0 | J23: =SUM(J22+H23-I23) -> 1066262 | L23: =K23-I23 -> 0 | V23: =V22+O23+P23-Q23-R23-S23-T23+U23 -> 5000000 | AA23: =AA22+Y23-Z23 -> 202452 | AC23: =AB23-Z23 -> 0 | AG23: =AG22+AE23-AF23 -> 466700 | AI23: =AH23-AF23 -> 0 | AP23: =AP22+AM23-AN23+AO23 -> 827481 | AR23: =AQ23-AN23 -> 0 | AW23: =AW22+AT23-AV23 -> 0 | AX23: =AU23-AV23 -> 0
E24: =E23+B24-D24 -> 140185 | F24: =C24-D24 -> 0 | J24: =SUM(J23+H24-I24) -> 1066262 | L24: =K24-I24 -> 0 | V24: =V23+O24+P24-Q24-R24-S24-T24+U24 -> 5000000 | AA24: =AA23+Y24-Z24 -> 202452 | AC24: =AB24-Z24 -> 0 | AG24: =AG23+AE24-AF24 -> 466700 | AI24: =AH24-AF24 -> 0 | AP24: =AP23+AM24-AN24+AO24 -> 827481 | AR24: =AQ24-AN24 -> 0 | AW24: =AW23+AT24-AV24 -> 0 | AX24: =AU24-AV24 -> 0
E25: =E24+B25-D25 -> 140185 | F25: =C25-D25 -> 0 | J25: =SUM(J24+H25-I25) -> 1066262 | L25: =K25-I25 -> 0 | V25: =V24+O25+P25-Q25-R25-S25-T25+U25 -> 5000000 | AA25: =AA24+Y25-Z25 -> 202452 | AC25: =AB25-Z25 -> 0 | AG25: =AG24+AE25-AF25 -> 466700 | AI25: =AH25-AF25 -> 0 | AP25: =AP24+AM25-AN25+AO25 -> 827481 | AR25: =AQ25-AN25 -> 0 | AW25: =AW24+AT25-AV25 -> 0 | AX25: =AU25-AV25 -> 0
E26: =E25+B26-D26 -> 140185 | F26: =C26-D26 -> 0 | J26: =SUM(J25+H26-I26) -> 1066262 | L26: =K26-I26 -> 0 | V26: =V25+O26+P26-Q26-R26-S26-T26+U26 -> 5000000 | AA26: =AA25+Y26-Z26 -> 202452 | AC26: =AB26-Z26 -> 0 | AG26: =AG25+AE26-AF26 -> 466700 | AI26: =AH26-AF26 -> 0 | AP26: =AP25+AM26-AN26+AO26 -> 827481 | AR26: =AQ26-AN26 -> 0 | AW26: =AW25+AT26-AV26 -> 0 | AX26: =AU26-AV26 -> 0
E27: =E26+B27-D27 -> 140185 | F27: =C27-D27 -> 0 | J27: =SUM(J26+H27-I27) -> 1066262 | L27: =K27-I27 -> 0 | V27: =V26+O27+P27-Q27-R27-S27-T27+U27 -> 5000000 | AA27: =AA26+Y27-Z27 -> 202452 | AC27: =AB27-Z27 -> 0 | AG27: =AG26+AE27-AF27 -> 466700 | AI27: =AH27-AF27 -> 0 | AP27: =AP26+AM27-AN27+AO27 -> 827481 | AR27: =AQ27-AN27 -> 0 | AW27: =AW26+AT27-AV27 -> 0 | AX27: =AU27-AV27 -> 0
E28: =E27+B28-D28 -> 140185 | F28: =C28-D28 -> 0 | J28: =SUM(J27+H28-I28) -> 1066262 | L28: =K28-I28 -> 0 | V28: =V27+O28+P28-Q28-R28-S28-T28+U28 -> 5000000 | AA28: =AA27+Y28-Z28 -> 202452 | AC28: =AB28-Z28 -> 0 | AG28: =AG27+AE28-AF28 -> 466700 | AI28: =AH28-AF28 -> 0 | AP28: =AP27+AM28-AN28+AO28 -> 827481 | AR28: =AQ28-AN28 -> 0 | AW28: =AW27+AT28-AV28 -> 0 | AX28: =AU28-AV28 -> 0
... E190: =E189+B190-D190 -> 140185 | F190: =C190-D190 -> 0 | J190: =SUM(J189+H190-I190) -> 1066262 | L190: =K190-I190 -> 0 | V190: =V189+O190+P190-Q190-R190-S190-T190+U190 -> 5000000 | AA190: =AA189+Y190-Z190 -> 202452 | AC190: =AB190-Z190 -> 0 | AG190: =AG189+AE190-AF190 -> 466700 | AI190: =AH190-AF190 -> 0 | AP190: =AP189+AM190-AN190+AO190 -> 827481 | AR190: =AQ190-AN190 -> 0 | AW190: =AW189+AT190-AV190 -> 0 | AX190: =AU190-AV190 -> 0
F191: =SUM(F6:F190) -> 0 | L191: =SUM(L6:L190) -> 0 | T191: =SUM(T6:T190) -> 0 | U191: =SUM(U6:U190) -> 0 | W191: =SUM(W6:W190) -> 0 | AC191: =SUM(AC6:AC190) -> 0 | AI191: =SUM(AI6:AI190) -> 0 | AO191: =SUM(AO6:AO190) -> 0 | AR191: =SUM(AR6:AR190) -> 0 | AX191: =SUM(AX6:AX190) -> 0
AW193: PROFIT | AX193: =F191+L191+U191+W191+AC191+AI191+AO191+AR191+AX191 -> 0
B197: DIGI POS | H197: EDC FASTPAY | O197: BRIMO C1 | Y197: 3 SAKTI | AE197: RITA PPOB | AM197: PEGADAIAN | AT197: SIDOMPUL

Sheet 2024
B2: DESEMBER | C2: NOVEMBER | D2: OKTOBER | E2: SEPTEMBER | F2: AGUSTUS | G2: JULI | H2: JUNI | I2: MEI | J2: APRIL | K2: JAN FEB MAR
A5: KIOS | B5: 6736076 | C5: 3518375 | D5: 1890591 | E5: 4499562 | F5: 2567375 | G5: -1458391 | H5: 2555483 | I5: 2113897 | J5: 3489297 | K5: 0
A6: TOTAL KIOS | B6: 25912265 | C6: 19176189 | D6: 15657814 | E6: 13767223 | F6: 9267661 | G6: 6700286 | H6: 8158677 | I6: 5603194 | J6: =K6+J5 -> 3489297 | K6: 0
A8: AGEN | B8: 24792031 | C8: 21861367 | D8: 24004620 | E8: 18767401 | F8: 20866441 | G8: 17920671 | H8: 16242718 | I8: 17103881 | J8: 14759863 | K8: 38029681
A9: TOTAL AGEN | B9: 214348674 | C9: 189556643 | D9: 167695276 | E9: 143690656 | F9: 124923255 | G9: 104056814 | H9: 86136143 | I9: 69893425 | J9: =K9+J8 -> 52789544 | K9: 38029681
A11: FEE BRILINK | B11: 1907600 | C11: 2099950 | D11: 2077612 | E11: 1890000 | F11: 1603550 | G11: 1803050 | H11: 1405350 | I11: 1332856 | J11: 0 | K11: 0
A12: TOTAL FEE BRILINK | B12: 14119968 | C12: 12212368 | D12: 10112418 | E12: 8034806 | F12: 6144806 | G12: 4541256 | H12: 2738206 | I12: 1332856 | J12: 0 | K12: 0
A14: PENGELUARAN LAINNYA | B14: 19892488 | C14: 14581532 | D14: 11071123 | E14: 15509111 | F14: 20365030 | G14: 14480500 | H14: 19615000 | I14: 18835598 | J14: 13133275 | K14: 0
A15: TOTAL | B15: 147483657 | C15: 127591169 | D15: 113009637 | E15: 101938514 | F15: 86429403 | G15: 66064373 | H15: 51583873 | I15: 31968873 | J15: =K15+J14 -> 13133275 | K15: 0
A17: PENGELUARAN PULSA | B17: 340297 | C17: 374431 | D17: 13999 | E17: 252935 | F17: 358660 | G17: 655137 | H17: 402282 | I17: 0 | J17: 0 | K17: 0
A18: TOTAL | B18: 2397741 | C18: 2057444 | D18: 1683013 | E18: 1669014 | F18: 1416079 | G18: 1057419 | H18: 402282 | I18: 0 | J18: 0 | K18: 0
A20: PENGELUARAN AIR TENGKI | B20: 0 | C20: 0 | D20: 425000 | E20: 200000 | F20: 300000 | G20: 220000 | H20: 0 | I20: 0 | J20: 0 | K20: 0
A21: TOTAL | B21: 1145000 | C21: 1145000 | D21: 1145000 | E21: 720000 | F21: 520000 | G21: 220000 | H21: 0 | I21: 0 | J21: 0 | K21: 0
A23: PENGELUARAN PULSA LISTRIK | B23: 513906 | C23: 244500 | D23: 291600 | E23: 362900 | F23: 385000 | G23: 257100 | H23: 371400 | I23: 0 | J23: 0 | K23: 0
A24: TOTAL | B24: 2426406 | C24: 1912500 | D24: 1668000 | E24: 1376400 | F24: 1013500 | G24: 628500 | H24: 371400 | I24: 0 | J24: 0 | K24: 0
A26: TOTAL PENGELUARAN | B26: 195042349 | C26: 174295658 | D26: 159095195 | E26: 147293473 | F26: 130968527 | G26: 109559837 | H26: 93947100 | I26: 73558418 | J26: 54722820 | K26: 41589545
A28: TOTAL PEMASUKAN | B28: 19306325 | C28: 15260985 | D28: 8600081 | E28: -3602817 | F28: -6045272 | G28: -5503023 | H28: -7810957 | I28: -3664993 | J28: -1933276 | K28: -3559864
A30: UANG YANG ADA | B30: 133724743 | C30: 105729327 | D30: 91020903 | E30: 70524414 | F30: 81598897 | G30: 68894771 | H30: 59286728 | I30: 48368209 | J30: 54674029 | K30: 76110222

Sheet 2025
B2: DESEMBER | C2: NOVEMBER | D2: OKTOBER | E2: SEPTEMBER | F2: AGUSTUS | G2: JULI | H2: JUNI | I2: MEI | J2: APRIL | K2: MARET | L2: FEBRUARI | M2: JANUARI
A5: KIOS | B5: -6889505 | C5: -834061 | D5: -3305529 | E5: 9364327 | F5: -179056 | G5: 4574928 | H5: 4076551 | I5: 5879199 | J5: 4290223 | K5: 4579996 | L5: 6539685 | M5: 42416 | N5: 0
A6: TOTAL KIOS | B6: 28139174 | C6: 35028679 | D6: 35862740 | E6: 39168269 | F6: 29803942 | G6: 29982998 | H6: 25408070 | I6: 21331519 | J6: 15452320 | K6: 11162097 | L6: 6582101 | M6: 42416 | N6: 0
A8: BELANJA KIOS | B8: 29514500 | C8: 18818500 | D8: 26242500 | E8: 14833000 | F8: 28569000 | G8: 31059000 | H8: 27456000 | I8: 28179500 | J8: 30389000 | K8: 33703000
A9: TOTAL | B9: 268764000 | C9: 239249500 | D9: 220431000 | E9: 194188500 | F9: 179355500 | G9: 150786500 | H9: 119727500 | I9: 92271500 | J9: 64092000 | K9: 33703000
A11: AMBIL BARANG KIOS | B11: 2339000 | C11: 1497000 | D11: 2043500 | E11: 1921000 | F11: 1693500 | G11: 1958500 | H11: 1660500 | I11: 2470000 | J11: 1748000 | K11: 1185000
A12: TOTAL | B12: 18516000 | C12: 16177000 | D12: 14680000 | E12: 12636500 | F12: 10715500 | G12: 9022000 | H12: 7063500 | I12: 5403000 | J12: 2933000 | K12: 1185000
A14: AGEN BAOMEKOT | B14: 19313911 | C14: 19766714 | D14: 16995299 | E14: 17363421 | F14: 20977138 | G14: 24093815 | H14: 22988038 | I14: 19171325 | J14: 19187887 | K14: 21238370 | L14: 25308870 | M14: 19485772 | N14: 0
B15: 245890560 | C15: 226576649 | D15: 206809935 | E15: 189814636 | F15: 172451215 | G15: 151474077 | H15: =I15+H14 -> 127380262 | I15: =J15+I14 -> 104392224 | J15: =K15+J14 -> 85220899 | K15: =L15+K14 -> 66033012 | L15: =M15+L14 -> 44794642 | M15: =N15+M14 -> 19485772
A16: PENGELUARAN
A17: BIAYA TOP UP | B17: 0 | C17: 0 | D17: 0 | E17: 0 | F17: 20500 | G17: 24500
B18: 45000 | C18: 45000 | D18: 45000 | E18: 45000 | F18: 45000 | G18: 24500
A19: ADMIN BULANAN | B19: 9000 | C19: 9000 | D19: 9000 | E19: 9000 | F19: 8000 | G19: 15500
B20: 59500 | C20: 50500 | D20: 41500 | E20: 32500 | F20: 23500 | G20: 15500
A21: DATA | B21: 309300 | C21: 230000 | D21: 286997 | E21: 239998 | F21: 234996 | G21: 215000
B22: 1516291 | C22: 1206991 | D22: 976991 | E22: 689994 | F22: 449996 | G22: 215000
A23: AIR GALON | B23: 0 | C23: 5000 | D23: 0 | E23: 0 | F23: 0 | G23: 5000
B24: 10000 | C24: 10000 | D24: 5000 | E24: 5000 | F24: 5000 | G24: 5000
A25: LISTRIK | B25: 101400 | C25: 0 | D25: 101400 | E25: 101400 | F25: 101400 | G25: 101400
B26: 507000 | C26: 405600 | D26: 405600 | E26: 304200 | F26: 202800 | G26: 101400
A27: C | B27: 1564000 | C27: 1538000 | D27: 1703000 | E27: 1956500 | F27: 1918000 | G27: 1389000
B28: 10068500 | C28: 8504500 | D28: 6966500 | E28: 5263500 | F28: 3307000 | G28: 1389000
A29: ELINK | B29: 0 | C29: 0 | D29: 0 | E29: 0 | F29: 0 | G29: 420000
B30: 420000 | C30: 420000 | D30: 420000 | E30: 420000 | F30: 420000 | G30: 420000
A31: SEWA TEMPAT | B31: 0 | C31: 0 | D31: 0 | E31: 0 | F31: 0 | G31: 0
B32: 0 | C32: 0 | D32: 0 | E32: 0 | F32: 0 | G32: 0
A33: LAINNYA | B33: 1140934 | C33: 433200 | D33: 89725 | E33: 1523000 | F33: 114030 | G33: 55699
B34: 3356588 | C34: 2215654 | D34: 1782454 | E34: 1692729 | F34: 169729 | G34: 55699
A35: TOTAL PENGELUARAN | B35: 3124634 | C35: 2215200 | D35: 2190122 | E35: 3829898 | F35: 2396926 | G35: 2226099
B36: 15982879 | C36: 12858245 | D36: 10643045 | E36: 8452923 | F36: 4623025 | G36: 2226099
A37: PROFIT BERSIH | B37: 16189277 | C37: 17551514 | D37: 14805177 | E37: 13533523 | F37: 18580212 | G37: 21867716 | H37: =H14-H35 -> 22988038 | I37: =I14-I35 -> 19171325 | J37: =J14-J35 -> 19187887 | K37: =K14-K35 -> 21238370 | L37: =L14-L35 -> 25308870 | M37: =M14-M35 -> 19485772
B38: 229907681 | C38: 213718404 | D38: 196166890 | E38: 181361713 | F38: 167828190 | G38: 149247978 | H38: =I38+H37 -> 127380262 | I38: =J38+I37 -> 104392224 | J38: =K38+J37 -> 85220899 | K38: =L38+K37 -> 66033012 | L38: =M38+L37 -> 44794642 | M38: =N38+M37 -> 19485772
A40: AGEN SIKU | B40: 9976089 | C40: 11202777 | D40: 9005778 | E40: 9409748 | F40: 8548510 | G40: 11055340 | H40: 10238175 | I40: 8544129 | J40: 7682213 | K40: 4612351
B41: 90275110 | C41: 80299021 | D41: 69096244 | E41: 60090466 | F41: 50680718 | G41: 42132208 | H41: =I41+H40 -> 31076868 | I41: =J41+I40 -> 20838693 | J41: =K41+J40 -> 12294564 | K41: =L41+K40 -> 4612351 | L41: =M66+L40 -> 0 | M41: =N66+M40 -> 0
A42: PENGELUARAN
A43: BIAYA TOP UP | B43: 0 | C43: 0 | D43: 0 | E43: 0 | F43: 9000 | G43: 13000 | K43: 200000
B44: 222000 | C44: 222000 | D44: 222000 | E44: 222000 | F44: 222000 | G44: 213000 | H44: =I44+H43 -> 200000 | I44: =J44+I43 -> 200000 | J44: =K44+J43 -> 200000 | K44: =L44+K43 -> 200000
A45: ADMIN BULANAN | B45: 9000 | C45: 9000 | D45: 9000 | E45: 9000 | F45: 8000 | G45: 18884 | K45: 200000
B46: 262884 | C46: 253884 | D46: 244884 | E46: 235884 | F46: 226884 | G46: 218884 | H46: =I46+H45 -> 200000 | I46: =J46+I45 -> 200000 | J46: =K46+J45 -> 200000 | K46: =L46+K45 -> 200000
A47: DATA | B47: 132198 | C47: 108496 | D47: 16499 | E47: 107499 | F47: 105996 | G47: 96998 | K47: 1000000
...

Sheet JAN
A1: KETERANGAN EDIT : | B1: WARNA
C3: 30 & 31 Jan | D3: 26 - 29 Jan | E3: 20 & 25 Jan | F3: 46041 | G3: 16 - 17 - 18 jan | H3: 46037 | I3: 46036 | J3: 46035 | K3: 11 & 12 Jan | L3: 9 & 10 Jan | M3: 46030 | N3: 46029 | O3: 46028 | P3: 4 - 5 JAN | Q3: 46025 | R3: 1 & 2 Jan | S3: 28 - 31 Dec
